Workbook
Name ___SE2: #REF!
Name ___SE2: #REF!
Name ___SE2: #REF!
Name ___SE2: #REF!
Name ___SE2: #REF!
Name ___SE2: #REF!
Name ___xlc_DefaultDisplayOption___: "caption"
Name ___xlc_DisplayNullValues___: TRUE
Name ___xlc_DisplayNullValuesAs___: 0
Name ___xlc_PromptForInsertOnDrill___: FALSE
Name ___xlc_SuppressNULLSOnDrill___: FALSE
Name ___xlc_SuppressZerosOnDrill___: FALSE
Name __123Graph_A: #REF!
Name __123Graph_A: #REF!
Name __123Graph_A: #REF!
Name __123Graph_A: #REF!
Name __123Graph_A: #REF!
Name __123Graph_ALK: #REF!
Name __123Graph_ALK: #REF!
Name __123Graph_ALK: #REF!
Name __123Graph_ALK: #REF!
Name __123Graph_ALK: #REF!
Name __123Graph_AMALB: #REF!
Name __123Graph_AOTH: #REF!
Name __123Graph_ATOTAL: #REF!
Name __123Graph_B: #REF!
Name __123Graph_B: #REF!
Name __123Graph_B: #REF!
Name __123Graph_B: #REF!
Name __123Graph_B: #REF!
Name __123Graph_BLK: #REF!
Name __123Graph_BLK: #REF!
Name __123Graph_BLK: #REF!
Name __123Graph_BLK: #REF!
Name __123Graph_BLK: #REF!
Name __123Graph_BMALB: #REF!
Name __123Graph_BOTH: #REF!
Name __123Graph_C: #REF!
Name __123Graph_C: #REF!
Name __123Graph_C: #REF!
Name __123Graph_C: #REF!
Name __123Graph_C: #REF!
Name __123Graph_CLK: #REF!
Name __123Graph_CLK: #REF!
Name __123Graph_CLK: #REF!
Name __123Graph_CLK: #REF!
Name __123Graph_CLK: #REF!
Name __123Graph_CMALB: #REF!
Name __123Graph_COTH: #REF!
Name __123Graph_D: #REF!
Name __123Graph_D: #REF!
Name __123Graph_D: #REF!
Name __123Graph_D: #REF!
Name __123Graph_D: #REF!
Name __123Graph_DLK: #REF!
Name __123Graph_DLK: #REF!
Name __123Graph_DLK: #REF!
Name __123Graph_DLK: #REF!
Name __123Graph_DLK: #REF!
Name __123Graph_DMALB: #REF!

Sheet GR (for admin only)
B1: 1 | C1: =B1+1 -> 2 | D1: =C1+1 -> 3 | E1: =D1+1 -> 4 | F1: =E1+1 -> 5 | I1: =#REF!+1 -> #REF! | J1: =I1+1 -> #REF! | L1: =J1+1 -> #REF! | N1: =#REF!+1 -> #REF! | P1: =#REF!+1 -> #REF! | R1: =#REF!+1 -> #REF!
C2: ='KPS #48'!C2 -> 48
B3: 44753 | C3: =TODAY() -> 46168 | G3: =SUM(G6:G99) -> #NAME? | H3: =SUM(H6:H99) -> #NAME? | J3: ="Arrival "&C2&" (in Box)" -> Arrival 48 (in Box)
A4: Partner | B4: Partner | C4: Segment | D4: Code | E4: Brand | F4: AE / Manager | G4: Status Delivery to DC | I4: Partial/No | J4: Senin | K4: GR | L4: Selasa | M4: GR | N4: Rabu | O4: GR | P4: Kamis | Q4: GR | R4: Jumat | S4: GR | T4: Sabtu | U4: GR | V4: Minggu | W4: GR | X4: Total Plan | Y4: Total GR | Z4: Remarks
G5: Outstand | H5: PO | J5: ='KPS #48'!J5 -> 45985 | L5: =J5+1 -> 45986 | N5: =L5+1 -> 45987 | P5: =N5+1 -> 45988 | R5: =P5+1 -> 45989 | T5: =R5+1 -> 45990 | V5: =T5+1 -> 45991 | AA5: Arrival In stick | AB5: po in stick | AC5: var
A6: =D6 -> PSP12 | B6: CV Gunung Batu Penjuru | C6: SKT 12 | D6: PSP12 | E6: Pasopati Skt 12S | F6: Jose | Andry | G6: {=_xludf.XLOOKUP(D6,'KPS #48'!D:D,'KPS #48'!G:G,0)} -> #NAME? | H6: {=_xludf.XLOOKUP(D6,'KPS #48'!D:D,'KPS #48'!H:H,0)} -> #NAME? | I6: =IF(AND(H6=0,G6=0),"No Delivery",IF(COUNTA(J6,L6,N6,P6,R6,T6,V6)=1,"Delivery",IF(COUNTA(J6,L6,N6,P6,R6,T6,V6)>1,"Partial Delivery",IF(COUNTA(J6,L6,N6,P6,R6,T6,V6)=0,"Will be Updated")))) -> #NAME? | J6: {=_xludf.XLOOKUP(D6,'KPS #48'!D:D,'KPS #48'!J:J,0)} -> #NAME? | K6: =_xludf.XLOOKUP($D6,#REF!,#REF!,0) -> #NAME? | L6: {=_xludf.XLOOKUP(D6,'KPS #48'!D:D,'KPS #48'!L:L,0)} -> #NAME? | M6: =_xludf.XLOOKUP($D6,#REF!,#REF!,0) -> #NAME? | N6: {=_xludf.XLOOKUP(D6,'KPS #48'!D:D,'KPS #48'!N:N,0)} -> #NAME? | O6: =_xludf.XLOOKUP($D6,#REF!,#REF!,0) -> #NAME? | P6: {=_xludf.XLOOKUP(D6,'KPS #48'!D:D,'KPS #48'!P:P,0)} -> #NAME? | Q6: =_xludf.XLOOKUP($D6,#REF!,#REF!,0) -> #NAME? | R6: {=_xludf.XLOOKUP(D6,'KPS #48'!D:D,'KPS #48'!R:R,0)} -> #NAME? | S6: =_xludf.XLOOKUP($D6,#REF!,#REF!,0) -> #NAME? | T6: {=_xludf.XLOOKUP(D6,'KPS #48'!D:D,'KPS #48'!T:T,0)} -> #NAME? | U6: =_xludf.XLOOKUP($D6,#REF!,#REF!,0) -> #NAME? | V6: {=_xludf.XLOOKUP(D6,'KPS #48'!D:D,'KPS #48'!V:V,0)} -> #NAME? | W6: =_xludf.XLOOKUP($D6,#REF!,#REF!,0) -> #NAME? | X6: =SUM(V6,T6,R6,P6,N6,L6,J6) -> #NAME? | Y6: =SUM(W6,U6,S6,Q6,O6,M6,K6) -> #NAME? | AA6: =X6*IFERROR(VLOOKUP(D6,'Brand List'!$B:$D,3,0),0) -> #NAME? | AB6: =H6*IFERROR(VLOOKUP(D6,'Brand List'!$B:$D,3,0),0) -> #NAME? | AC6: =AA6-AB6 -> #NAME? | AD6: =_xlfn.XLOOKUP(D6,[1]Summary!$E:$E,[1]Summary!$L:$L,0) -> 0 | AE6: =AD6*X6 -> #NAME?
A7: =D7 -> BGS12 | B7: PT Anak Sakti | C7: SKT 12 | D7: BGS12 | E7: Bagas Skt 12S | F7: Vincent | Johan | G7: {=_xludf.XLOOKUP(D7,'KPS #48'!D:D,'KPS #48'!G:G,0)} -> #NAME? | H7: {=_xludf.XLOOKUP(D7,'KPS #48'!D:D,'KPS #48'!H:H,0)} -> #NAME? | I7: =IF(AND(H7=0,G7=0),"No Delivery",IF(COUNTA(J7,L7,N7,P7,R7,T7,V7)=1,"Delivery",IF(COUNTA(J7,L7,N7,P7,R7,T7,V7)>1,"Partial Delivery",IF(COUNTA(J7,L7,N7,P7,R7,T7,V7)=0,"Will be Updated")))) -> #NAME? | J7: {=_xludf.XLOOKUP(D7,'KPS #48'!D:D,'KPS #48'!J:J,0)} -> #NAME? | K7: =_xludf.XLOOKUP($D7,#REF!,#REF!,0) -> #NAME? | L7: {=_xludf.XLOOKUP(D7,'KPS #48'!D:D,'KPS #48'!L:L,0)} -> #NAME? | M7: =_xludf.XLOOKUP($D7,#REF!,#REF!,0) -> #NAME? | N7: {=_xludf.XLOOKUP(D7,'KPS #48'!D:D,'KPS #48'!N:N,0)} -> #NAME? | O7: =_xludf.XLOOKUP($D7,#REF!,#REF!,0) -> #NAME? | P7: {=_xludf.XLOOKUP(D7,'KPS #48'!D:D,'KPS #48'!P:P,0)} -> #NAME? | Q7: =_xludf.XLOOKUP($D7,#REF!,#REF!,0) -> #NAME? | R7: {=_xludf.XLOOKUP(D7,'KPS #48'!D:D,'KPS #48'!R:R,0)} -> #NAME? | S7: =_xludf.XLOOKUP($D7,#REF!,#REF!,0) -> #NAME? | T7: {=_xludf.XLOOKUP(D7,'KPS #48'!D:D,'KPS #48'!T:T,0)} -> #NAME? | U7: =_xludf.XLOOKUP($D7,#REF!,#REF!,0) -> #NAME? | V7: {=_xludf.XLOOKUP(D7,'KPS #48'!D:D,'KPS #48'!V:V,0)} -> #NAME? | W7: =_xludf.XLOOKUP($D7,#REF!,#REF!,0) -> #NAME? | X7: =SUM(V7,T7,R7,P7,N7,L7,J7) -> #NAME? | Y7: =SUM(W7,U7,S7,Q7,O7,M7,K7) -> #NAME? | AA7: =X7*IFERROR(VLOOKUP(D7,'Brand List'!$B:$D,3,0),0) -> #NAME? | AB7: =H7*IFERROR(VLOOKUP(D7,'Brand List'!$B:$D,3,0),0) -> #NAME? | AC7: =AA7-AB7 -> #NAME? | AD7: =_xlfn.XLOOKUP(D7,[1]Summary!$E:$E,[1]Summary!$L:$L,0) -> 0 | AE7: =AD7*X7 -> #NAME?
A8: =D8 -> BSH12 | B8: PT Anak Sakti | C8: SKT 12 | D8: BSH12 | E8: Bagas Versi Sugih Skt 12S | F8: Vincent | Johan | G8: {=_xludf.XLOOKUP(D8,'KPS #48'!D:D,'KPS #48'!G:G,0)} -> #NAME? | H8: {=_xludf.XLOOKUP(D8,'KPS #48'!D:D,'KPS #48'!H:H,0)} -> #NAME? | I8: =IF(AND(H8=0,G8=0),"No Delivery",IF(COUNTA(J8,L8,N8,P8,R8,T8,V8)=1,"Delivery",IF(COUNTA(J8,L8,N8,P8,R8,T8,V8)>1,"Partial Delivery",IF(COUNTA(J8,L8,N8,P8,R8,T8,V8)=0,"Will be Updated")))) -> #NAME? | J8: {=_xludf.XLOOKUP(D8,'KPS #48'!D:D,'KPS #48'!J:J,0)} -> #NAME? | K8: =_xludf.XLOOKUP($D8,#REF!,#REF!,0) -> #NAME? | L8: {=_xludf.XLOOKUP(D8,'KPS #48'!D:D,'KPS #48'!L:L,0)} -> #NAME? | M8: =_xludf.XLOOKUP($D8,#REF!,#REF!,0) -> #NAME? | N8: {=_xludf.XLOOKUP(D8,'KPS #48'!D:D,'KPS #48'!N:N,0)} -> #NAME? | O8: =_xludf.XLOOKUP($D8,#REF!,#REF!,0) -> #NAME? | P8: {=_xludf.XLOOKUP(D8,'KPS #48'!D:D,'KPS #48'!P:P,0)} -> #NAME? | Q8: =_xludf.XLOOKUP($D8,#REF!,#REF!,0) -> #NAME? | R8: {=_xludf.XLOOKUP(D8,'KPS #48'!D:D,'KPS #48'!R:R,0)} -> #NAME? | S8: =_xludf.XLOOKUP($D8,#REF!,#REF!,0) -> #NAME? | T8: {=_xludf.XLOOKUP(D8,'KPS #48'!D:D,'KPS #48'!T:T,0)} -> #NAME? | U8: =_xludf.XLOOKUP($D8,#REF!,#REF!,0) -> #NAME? | V8: {=_xludf.XLOOKUP(D8,'KPS #48'!D:D,'KPS #48'!V:V,0)} -> #NAME? | W8: =_xludf.XLOOKUP($D8,#REF!,#REF!,0) -> #NAME? | X8: =SUM(V8,T8,R8,P8,N8,L8,J8) -> #NAME? | Y8: =SUM(W8,U8,S8,Q8,O8,M8,K8) -> #NAME? | AA8: =X8*IFERROR(VLOOKUP(D8,'Brand List'!$B:$D,3,0),0) -> #NAME? | AB8: =H8*IFERROR(VLOOKUP(D8,'Brand List'!$B:$D,3,0),0) -> #NAME? | AC8: =AA8-AB8 -> #NAME? | AD8: =_xlfn.XLOOKUP(D8,[1]Summary!$E:$E,[1]Summary!$L:$L,0) -> 0 | AE8: =AD8*X8 -> #NAME?
A9: =D9 -> PRU12 | B9: PT Anak Sakti | C9: SKT 12 | D9: PRU12 | E9: Prabu Skt 12S | F9: Vincent | Johan | G9: {=_xludf.XLOOKUP(D9,'KPS #48'!D:D,'KPS #48'!G:G,0)} -> #NAME? | H9: {=_xludf.XLOOKUP(D9,'KPS #48'!D:D,'KPS #48'!H:H,0)} -> #NAME? | I9: =IF(AND(H9=0,G9=0),"No Delivery",IF(COUNTA(J9,L9,N9,P9,R9,T9,V9)=1,"Delivery",IF(COUNTA(J9,L9,N9,P9,R9,T9,V9)>1,"Partial Delivery",IF(COUNTA(J9,L9,N9,P9,R9,T9,V9)=0,"Will be Updated")))) -> #NAME? | J9: {=_xludf.XLOOKUP(D9,'KPS #48'!D:D,'KPS #48'!J:J,0)} -> #NAME? | K9: =_xludf.XLOOKUP($D9,#REF!,#REF!,0) -> #NAME? | L9: {=_xludf.XLOOKUP(D9,'KPS #48'!D:D,'KPS #48'!L:L,0)} -> #NAME? | M9: =_xludf.XLOOKUP($D9,#REF!,#REF!,0) -> #NAME? | N9: {=_xludf.XLOOKUP(D9,'KPS #48'!D:D,'KPS #48'!N:N,0)} -> #NAME? | O9: =_xludf.XLOOKUP($D9,#REF!,#REF!,0) -> #NAME? | P9: {=_xludf.XLOOKUP(D9,'KPS #48'!D:D,'KPS #48'!P:P,0)} -> #NAME? | Q9: =_xludf.XLOOKUP($D9,#REF!,#REF!,0) -> #NAME? | R9: {=_xludf.XLOOKUP(D9,'KPS #48'!D:D,'KPS #48'!R:R,0)} -> #NAME? | S9: =_xludf.XLOOKUP($D9,#REF!,#REF!,0) -> #NAME? | T9: {=_xludf.XLOOKUP(D9,'KPS #48'!D:D,'KPS #48'!T:T,0)} -> #NAME? | U9: =_xludf.XLOOKUP($D9,#REF!,#REF!,0) -> #NAME? | V9: {=_xludf.XLOOKUP(D9,'KPS #48'!D:D,'KPS #48'!V:V,0)} -> #NAME? | W9: =_xludf.XLOOKUP($D9,#REF!,#REF!,0) -> #NAME? | X9: =SUM(V9,T9,R9,P9,N9,L9,J9) -> #NAME? | Y9: =SUM(W9,U9,S9,Q9,O9,M9,K9) -> #NAME? | AA9: =X9*IFERROR(VLOOKUP(D9,'Brand List'!$B:$D,3,0),0) -> #NAME? | AB9: =H9*IFERROR(VLOOKUP(D9,'Brand List'!$B:$D,3,0),0) -> #NAME? | AC9: =AA9-AB9 -> #NAME? | AD9: =_xlfn.XLOOKUP(D9,[1]Summary!$E:$E,[1]Summary!$L:$L,0) -> 0 | AE9: =AD9*X9 -> #NAME?
A10: =D10 -> KAM12 | B10: CV Asia Setia Putra | C10: SKT 12 | D10: KAM12 | E10: Kama Skt 12S | F10: Malvin | Lariza | G10: {=_xludf.XLOOKUP(D10,'KPS #48'!D:D,'KPS #48'!G:G,0)} -> #NAME? | H10: {=_xludf.XLOOKUP(D10,'KPS #48'!D:D,'KPS #48'!H:H,0)} -> #NAME? | I10: =IF(AND(H10=0,G10=0),"No Delivery",IF(COUNTA(J10,L10,N10,P10,R10,T10,V10)=1,"Delivery",IF(COUNTA(J10,L10,N10,P10,R10,T10,V10)>1,"Partial Delivery",IF(COUNTA(J10,L10,N10,P10,R10,T10,V10)=0,"Will be Updated")))) -> #NAME? | J10: {=_xludf.XLOOKUP(D10,'KPS #48'!D:D,'KPS #48'!J:J,0)} -> #NAME? | K10: =_xludf.XLOOKUP($D10,#REF!,#REF!,0) -> #NAME? | L10: {=_xludf.XLOOKUP(D10,'KPS #48'!D:D,'KPS #48'!L:L,0)} -> #NAME? | M10: =_xludf.XLOOKUP($D10,#REF!,#REF!,0) -> #NAME? | N10: {=_xludf.XLOOKUP(D10,'KPS #48'!D:D,'KPS #48'!N:N,0)} -> #NAME? | O10: =_xludf.XLOOKUP($D10,#REF!,#REF!,0) -> #NAME? | P10: {=_xludf.XLOOKUP(D10,'KPS #48'!D:D,'KPS #48'!P:P,0)} -> #NAME? | Q10: =_xludf.XLOOKUP($D10,#REF!,#REF!,0) -> #NAME? | R10: {=_xludf.XLOOKUP(D10,'KPS #48'!D:D,'KPS #48'!R:R,0)} -> #NAME? | S10: =_xludf.XLOOKUP($D10,#REF!,#REF!,0) -> #NAME? | T10: {=_xludf.XLOOKUP(D10,'KPS #48'!D:D,'KPS #48'!T:T,0)} -> #NAME? | U10: =_xludf.XLOOKUP($D10,#REF!,#REF!,0) -> #NAME? | V10: {=_xludf.XLOOKUP(D10,'KPS #48'!D:D,'KPS #48'!V:V,0)} -> #NAME? | W10: =_xludf.XLOOKUP($D10,#REF!,#REF!,0) -> #NAME? | X10: =SUM(V10,T10,R10,P10,N10,L10,J10) -> #NAME? | Y10: =SUM(W10,U10,S10,Q10,O10,M10,K10) -> #NAME? | AA10: =X10*IFERROR(VLOOKUP(D10,'Brand List'!$B:$D,3,0),0) -> #NAME? | AB10: =H10*IFERROR(VLOOKUP(D10,'Brand List'!$B:$D,3,0),0) -> #NAME? | AC10: =AA10-AB10 -> #NAME? | AD10: =_xlfn.XLOOKUP(D10,[1]Summary!$E:$E,[1]Summary!$L:$L,0) -> 0 | AE10: =AD10*X10 -> #NAME?
A11: =D11 -> SBH12 | B11: PT Asia Marko | C11: SKT 12 | D11: SBH12 | E11: Sumbu Hijau Skt 12S | F11: Jose | Lariza | G11: {=_xludf.XLOOKUP(D11,'KPS #48'!D:D,'KPS #48'!G:G,0)} -> #NAME? | H11: {=_xludf.XLOOKUP(D11,'KPS #48'!D:D,'KPS #48'!H:H,0)} -> #NAME? | I11: =IF(AND(H11=0,G11=0),"No Delivery",IF(COUNTA(J11,L11,N11,P11,R11,T11,V11)=1,"Delivery",IF(COUNTA(J11,L11,N11,P11,R11,T11,V11)>1,"Partial Delivery",IF(COUNTA(J11,L11,N11,P11,R11,T11,V11)=0,"Will be Updated")))) -> #NAME? | J11: {=_xludf.XLOOKUP(D11,'KPS #48'!D:D,'KPS #48'!J:J,0)} -> #NAME? | K11: =_xludf.XLOOKUP($D11,#REF!,#REF!,0) -> #NAME? | L11: {=_xludf.XLOOKUP(D11,'KPS #48'!D:D,'KPS #48'!L:L,0)} -> #NAME? | M11: =_xludf.XLOOKUP($D11,#REF!,#REF!,0) -> #NAME? | N11: {=_xludf.XLOOKUP(D11,'KPS #48'!D:D,'KPS #48'!N:N,0)} -> #NAME? | O11: =_xludf.XLOOKUP($D11,#REF!,#REF!,0) -> #NAME? | P11: {=_xludf.XLOOKUP(D11,'KPS #48'!D:D,'KPS #48'!P:P,0)} -> #NAME? | Q11: =_xludf.XLOOKUP($D11,#REF!,#REF!,0) -> #NAME? | R11: {=_xludf.XLOOKUP(D11,'KPS #48'!D:D,'KPS #48'!R:R,0)} -> #NAME? | S11: =_xludf.XLOOKUP($D11,#REF!,#REF!,0) -> #NAME? | T11: {=_xludf.XLOOKUP(D11,'KPS #48'!D:D,'KPS #48'!T:T,0)} -> #NAME? | U11: =_xludf.XLOOKUP($D11,#REF!,#REF!,0) -> #NAME? | V11: {=_xludf.XLOOKUP(D11,'KPS #48'!D:D,'KPS #48'!V:V,0)} -> #NAME? | W11: =_xludf.XLOOKUP($D11,#REF!,#REF!,0) -> #NAME? | X11: =SUM(V11,T11,R11,P11,N11,L11,J11) -> #NAME? | Y11: =SUM(W11,U11,S11,Q11,O11,M11,K11) -> #NAME? | AA11: =X11*IFERROR(VLOOKUP(D11,'Brand List'!$B:$D,3,0),0) -> #NAME? | AB11: =H11*IFERROR(VLOOKUP(D11,'Brand List'!$B:$D,3,0),0) -> #NAME? | AC11: =AA11-AB11 -> #NAME? | AD11: =_xlfn.XLOOKUP(D11,[1]Summary!$E:$E,[1]Summary!$L:$L,0) -> 0 | AE11: =AD11*X11 -> #NAME?
A12: =D12 -> VER20 | B12: PT Djitoe | C12: SPM 20 | D12: VER20 | E12: Vermont Spm 20S | F12: Jose | Lariza | G12: {=_xludf.XLOOKUP(D12,'KPS #48'!D:D,'KPS #48'!G:G,0)} -> #NAME? | H12: {=_xludf.XLOOKUP(D12,'KPS #48'!D:D,'KPS #48'!H:H,0)} -> #NAME? | I12: =IF(AND(H12=0,G12=0),"No Delivery",IF(COUNTA(J12,L12,N12,P12,R12,T12,V12)=1,"Delivery",IF(COUNTA(J12,L12,N12,P12,R12,T12,V12)>1,"Partial Delivery",IF(COUNTA(J12,L12,N12,P12,R12,T12,V12)=0,"Will be Updated")))) -> #NAME? | J12: {=_xludf.XLOOKUP(D12,'KPS #48'!D:D,'KPS #48'!J:J,0)} -> #NAME? | K12: =_xludf.XLOOKUP($D12,#REF!,#REF!,0) -> #NAME? | L12: {=_xludf.XLOOKUP(D12,'KPS #48'!D:D,'KPS #48'!L:L,0)} -> #NAME? | M12: =_xludf.XLOOKUP($D12,#REF!,#REF!,0) -> #NAME? | N12: {=_xludf.XLOOKUP(D12,'KPS #48'!D:D,'KPS #48'!N:N,0)} -> #NAME? | O12: =_xludf.XLOOKUP($D12,#REF!,#REF!,0) -> #NAME? | P12: {=_xludf.XLOOKUP(D12,'KPS #48'!D:D,'KPS #48'!P:P,0)} -> #NAME? | Q12: =_xludf.XLOOKUP($D12,#REF!,#REF!,0) -> #NAME? | R12: {=_xludf.XLOOKUP(D12,'KPS #48'!D:D,'KPS #48'!R:R,0)} -> #NAME? | S12: =_xludf.XLOOKUP($D12,#REF!,#REF!,0) -> #NAME? | T12: {=_xludf.XLOOKUP(D12,'KPS #48'!D:D,'KPS #48'!T:T,0)} -> #NAME? | U12: =_xludf.XLOOKUP($D12,#REF!,#REF!,0) -> #NAME? | V12: {=_xludf.XLOOKUP(D12,'KPS #48'!D:D,'KPS #48'!V:V,0)} -> #NAME? | W12: =_xludf.XLOOKUP($D12,#REF!,#REF!,0) -> #NAME? | X12: =SUM(V12,T12,R12,P12,N12,L12,J12) -> #NAME? | Y12: =SUM(W12,U12,S12,Q12,O12,M12,K12) -> #NAME? | AA12: =X12*IFERROR(VLOOKUP(D12,'Brand List'!$B:$D,3,0),0) -> #NAME? | AB12: =H12*IFERROR(VLOOKUP(D12,'Brand List'!$B:$D,3,0),0) -> #NAME? | AC12: =AA12-AB12 -> #NAME? | AD12: =_xlfn.XLOOKUP(D12,[1]Summary!$E:$E,[1]Summary!$L:$L,0) -> 0 | AE12: =AD12*X12 -> #NAME?
A13: =D13 -> PRJ12 | B13: PT Sata Jaya Sejahtera | C13: SKT 12 | D13: PRJ12 | E13: Praja Skt 12S | F13: Nico | Lariza | G13: {=_xludf.XLOOKUP(D13,'KPS #48'!D:D,'KPS #48'!G:G,0)} -> #NAME? | H13: {=_xludf.XLOOKUP(D13,'KPS #48'!D:D,'KPS #48'!H:H,0)} -> #NAME? | I13: =IF(AND(H13=0,G13=0),"No Delivery",IF(COUNTA(J13,L13,N13,P13,R13,T13,V13)=1,"Delivery",IF(COUNTA(J13,L13,N13,P13,R13,T13,V13)>1,"Partial Delivery",IF(COUNTA(J13,L13,N13,P13,R13,T13,V13)=0,"Will be Updated")))) -> #NAME? | J13: {=_xludf.XLOOKUP(D13,'KPS #48'!D:D,'KPS #48'!J:J,0)} -> #NAME? | K13: =_xludf.XLOOKUP($D13,#REF!,#REF!,0) -> #NAME? | L13: {=_xludf.XLOOKUP(D13,'KPS #48'!D:D,'KPS #48'!L:L,0)} -> #NAME? | M13: =_xludf.XLOOKUP($D13,#REF!,#REF!,0) -> #NAME? | N13: {=_xludf.XLOOKUP(D13,'KPS #48'!D:D,'KPS #48'!N:N,0)} -> #NAME? | O13: =_xludf.XLOOKUP($D13,#REF!,#REF!,0) -> #NAME? | P13: {=_xludf.XLOOKUP(D13,'KPS #48'!D:D,'KPS #48'!P:P,0)} -> #NAME? | Q13: =_xludf.XLOOKUP($D13,#REF!,#REF!,0) -> #NAME? | R13: {=_xludf.XLOOKUP(D13,'KPS #48'!D:D,'KPS #48'!R:R,0)} -> #NAME? | S13: =_xludf.XLOOKUP($D13,#REF!,#REF!,0) -> #NAME? | T13: {=_xludf.XLOOKUP(D13,'KPS #48'!D:D,'KPS #48'!T:T,0)} -> #NAME? | U13: =_xludf.XLOOKUP($D13,#REF!,#REF!,0) -> #NAME? | V13: {=_xludf.XLOOKUP(D13,'KPS #48'!D:D,'KPS #48'!V:V,0)} -> #NAME? | W13: =_xludf.XLOOKUP($D13,#REF!,#REF!,0) -> #NAME? | X13: =SUM(V13,T13,R13,P13,N13,L13,J13) -> #NAME? | Y13: =SUM(W13,U13,S13,Q13,O13,M13,K13) -> #NAME? | AA13: =X13*IFERROR(VLOOKUP(D13,'Brand List'!$B:$D,3,0),0) -> #NAME? | AB13: =H13*IFERROR(VLOOKUP(D13,'Brand List'!$B:$D,3,0),0) -> #NAME? | AC13: =AA13-AB13 -> #NAME? | AD13: =_xlfn.XLOOKUP(D13,[1]Summary!$E:$E,[1]Summary!$L:$L,0) -> 0 | AE13: =AD13*X13 -> #NAME?
A14: =D14 -> PRL12 | B14: PT Sata Jaya Sejahtera | C14: SKT 12 | D14: PRL12 | E14: Praja Royal Skt 12S | F14: Nico | Lariza | G14: {=_xludf.XLOOKUP(D14,'KPS #48'!D:D,'KPS #48'!G:G,0)} -> #NAME? | H14: {=_xludf.XLOOKUP(D14,'KPS #48'!D:D,'KPS #48'!H:H,0)} -> #NAME? | I14: =IF(AND(H14=0,G14=0),"No Delivery",IF(COUNTA(J14,L14,N14,P14,R14,T14,V14)=1,"Delivery",IF(COUNTA(J14,L14,N14,P14,R14,T14,V14)>1,"Partial Delivery",IF(COUNTA(J14,L14,N14,P14,R14,T14,V14)=0,"Will be Updated")))) -> #NAME? | J14: {=_xludf.XLOOKUP(D14,'KPS #48'!D:D,'KPS #48'!J:J,0)} -> #NAME? | K14: =_xludf.XLOOKUP($D14,#REF!,#REF!,0) -> #NAME? | L14: {=_xludf.XLOOKUP(D14,'KPS #48'!D:D,'KPS #48'!L:L,0)} -> #NAME? | M14: =_xludf.XLOOKUP($D14,#REF!,#REF!,0) -> #NAME? | N14: {=_xludf.XLOOKUP(D14,'KPS #48'!D:D,'KPS #48'!N:N,0)} -> #NAME? | O14: =_xludf.XLOOKUP($D14,#REF!,#REF!,0) -> #NAME? | P14: {=_xludf.XLOOKUP(D14,'KPS #48'!D:D,'KPS #48'!P:P,0)} -> #NAME? | Q14: =_xludf.XLOOKUP($D14,#REF!,#REF!,0) -> #NAME? | R14: {=_xludf.XLOOKUP(D14,'KPS #48'!D:D,'KPS #48'!R:R,0)} -> #NAME? | S14: =_xludf.XLOOKUP($D14,#REF!,#REF!,0) -> #NAME? | T14: {=_xludf.XLOOKUP(D14,'KPS #48'!D:D,'KPS #48'!T:T,0)} -> #NAME? | U14: =_xludf.XLOOKUP($D14,#REF!,#REF!,0) -> #NAME? | V14: {=_xludf.XLOOKUP(D14,'KPS #48'!D:D,'KPS #48'!V:V,0)} -> #NAME? | W14: =_xludf.XLOOKUP($D14,#REF!,#REF!,0) -> #NAME? | X14: =SUM(V14,T14,R14,P14,N14,L14,J14) -> #NAME? | Y14: =SUM(W14,U14,S14,Q14,O14,M14,K14) -> #NAME? | Z14: PO kps 47 = 40 box arrive in Sat kps 46 | AA14: =X14*IFERROR(VLOOKUP(D14,'Brand List'!$B:$D,3,0),0) -> #NAME? | AB14: =H14*IFERROR(VLOOKUP(D14,'Brand List'!$B:$D,3,0),0) -> #NAME? | AC14: =AA14-AB14 -> #NAME? | AD14: =_xlfn.XLOOKUP(D14,[1]Summary!$E:$E,[1]Summary!$L:$L,0) -> 0 | AE14: =AD14*X14 -> #NAME?
A15: =D15 -> TRI20 | B15: PT Atraco Multiguna | C15: SKM HT 20 | D15: TRI20 | E15: Triton Skm Ht 20S | F15: Jose | Lariza | G15: {=_xludf.XLOOKUP(D15,'KPS #48'!D:D,'KPS #48'!G:G,0)} -> #NAME? | H15: {=_xludf.XLOOKUP(D15,'KPS #48'!D:D,'KPS #48'!H:H,0)} -> #NAME? | I15: =IF(AND(H15=0,G15=0),"No Delivery",IF(COUNTA(J15,L15,N15,P15,R15,T15,V15)=1,"Delivery",IF(COUNTA(J15,L15,N15,P15,R15,T15,V15)>1,"Partial Delivery",IF(COUNTA(J15,L15,N15,P15,R15,T15,V15)=0,"Will be Updated")))) -> #NAME? | J15: {=_xludf.XLOOKUP(D15,'KPS #48'!D:D,'KPS #48'!J:J,0)} -> #NAME? | K15: =_xludf.XLOOKUP($D15,#REF!,#REF!,0) -> #NAME? | L15: {=_xludf.XLOOKUP(D15,'KPS #48'!D:D,'KPS #48'!L:L,0)} -> #NAME? | M15: =_xludf.XLOOKUP($D15,#REF!,#REF!,0) -> #NAME? | N15: {=_xludf.XLOOKUP(D15,'KPS #48'!D:D,'KPS #48'!N:N,0)} -> #NAME? | O15: =_xludf.XLOOKUP($D15,#REF!,#REF!,0) -> #NAME? | P15: {=_xludf.XLOOKUP(D15,'KPS #48'!D:D,'KPS #48'!P:P,0)} -> #NAME? | Q15: =_xludf.XLOOKUP($D15,#REF!,#REF!,0) -> #NAME? | R15: {=_xludf.XLOOKUP(D15,'KPS #48'!D:D,'KPS #48'!R:R,0)} -> #NAME? | S15: =_xludf.XLOOKUP($D15,#REF!,#REF!,0) -> #NAME? | T15: {=_xludf.XLOOKUP(D15,'KPS #48'!D:D,'KPS #48'!T:T,0)} -> #NAME? | U15: =_xludf.XLOOKUP($D15,#REF!,#REF!,0) -> #NAME? | V15: {=_xludf.XLOOKUP(D15,'KPS #48'!D:D,'KPS #48'!V:V,0)} -> #NAME? | W15: =_xludf.XLOOKUP($D15,#REF!,#REF!,0) -> #NAME? | X15: =SUM(V15,T15,R15,P15,N15,L15,J15) -> #NAME? | Y15: =SUM(W15,U15,S15,Q15,O15,M15,K15) -> #NAME? | AA15: =X15*IFERROR(VLOOKUP(D15,'Brand List'!$B:$D,3,0),0) -> #NAME? | AB15: =H15*IFERROR(VLOOKUP(D15,'Brand List'!$B:$D,3,0),0) -> #NAME? | AC15: =AA15-AB15 -> #NAME? | AD15: =_xlfn.XLOOKUP(D15,[1]Summary!$E:$E,[1]Summary!$L:$L,0) -> 0 | AE15: =AD15*X15 -> #NAME?
A16: =D16 -> GSS12 | B16: PT Rukun Global Indojaya | C16: SKT 12 | D16: GSS12 | E16: Giri Seduh Sari Skt 12S | F16: Jose | Lariza | G16: {=_xludf.XLOOKUP(D16,'KPS #48'!D:D,'KPS #48'!G:G,0)} -> #NAME? | H16: {=_xludf.XLOOKUP(D16,'KPS #48'!D:D,'KPS #48'!H:H,0)} -> #NAME? | I16: =IF(AND(H16=0,G16=0),"No Delivery",IF(COUNTA(J16,L16,N16,P16,R16,T16,V16)=1,"Delivery",IF(COUNTA(J16,L16,N16,P16,R16,T16,V16)>1,"Partial Delivery",IF(COUNTA(J16,L16,N16,P16,R16,T16,V16)=0,"Will be Updated")))) -> #NAME? | J16: {=_xludf.XLOOKUP(D16,'KPS #48'!D:D,'KPS #48'!J:J,0)} -> #NAME? | K16: =_xludf.XLOOKUP($D16,#REF!,#REF!,0) -> #NAME? | L16: {=_xludf.XLOOKUP(D16,'KPS #48'!D:D,'KPS #48'!L:L,0)} -> #NAME? | M16: =_xludf.XLOOKUP($D16,#REF!,#REF!,0) -> #NAME? | N16: {=_xludf.XLOOKUP(D16,'KPS #48'!D:D,'KPS #48'!N:N,0)} -> #NAME? | O16: =_xludf.XLOOKUP($D16,#REF!,#REF!,0) -> #NAME? | P16: {=_xludf.XLOOKUP(D16,'KPS #48'!D:D,'KPS #48'!P:P,0)} -> #NAME? | Q16: =_xludf.XLOOKUP($D16,#REF!,#REF!,0) -> #NAME? | R16: {=_xludf.XLOOKUP(D16,'KPS #48'!D:D,'KPS #48'!R:R,0)} -> #NAME? | S16: =_xludf.XLOOKUP($D16,#REF!,#REF!,0) -> #NAME? | T16: {=_xludf.XLOOKUP(D16,'KPS #48'!D:D,'KPS #48'!T:T,0)} -> #NAME? | U16: =_xludf.XLOOKUP($D16,#REF!,#REF!,0) -> #NAME? | V16: {=_xludf.XLOOKUP(D16,'KPS #48'!D:D,'KPS #48'!V:V,0)} -> #NAME? | W16: =_xludf.XLOOKUP($D16,#REF!,#REF!,0) -> #NAME? | X16: =SUM(V16,T16,R16,P16,N16,L16,J16) -> #NAME? | Y16: =SUM(W16,U16,S16,Q16,O16,M16,K16) -> #NAME? | AA16: =X16*IFERROR(VLOOKUP(D16,'Brand List'!$B:$D,3,0),0) -> #NAME? | AB16: =H16*IFERROR(VLOOKUP(D16,'Brand List'!$B:$D,3,0),0) -> #NAME? | AC16: =AA16-AB16 -> #NAME? | AD16: =_xlfn.XLOOKUP(D16,[1]Summary!$E:$E,[1]Summary!$L:$L,0) -> 0 | AE16: =AD16*X16 -> #NAME?
A17: =D17 -> CTL16 | B17: PR Sejahtera Abadi | C17: SKM LT 16 | D17: CTL16 | E17: City Lite Lt 16S | F17: Malvin | Andry | G17: {=_xludf.XLOOKUP(D17,'KPS #48'!D:D,'KPS #48'!G:G,0)} -> #NAME? | H17: {=_xludf.XLOOKUP(D17,'KPS #48'!D:D,'KPS #48'!H:H,0)} -> #NAME? | I17: =IF(AND(H17=0,G17=0),"No Delivery",IF(COUNTA(J17,L17,N17,P17,R17,T17,V17)=1,"Delivery",IF(COUNTA(J17,L17,N17,P17,R17,T17,V17)>1,"Partial Delivery",IF(COUNTA(J17,L17,N17,P17,R17,T17,V17)=0,"Will be Updated")))) -> #NAME? | J17: {=_xludf.XLOOKUP(D17,'KPS #48'!D:D,'KPS #48'!J:J,0)} -> #NAME? | K17: =_xludf.XLOOKUP($D17,#REF!,#REF!,0) -> #NAME? | L17: {=_xludf.XLOOKUP(D17,'KPS #48'!D:D,'KPS #48'!L:L,0)} -> #NAME? | M17: =_xludf.XLOOKUP($D17,#REF!,#REF!,0) -> #NAME? | N17: {=_xludf.XLOOKUP(D17,'KPS #48'!D:D,'KPS #48'!N:N,0)} -> #NAME? | O17: =_xludf.XLOOKUP($D17,#REF!,#REF!,0) -> #NAME? | P17: {=_xludf.XLOOKUP(D17,'KPS #48'!D:D,'KPS #48'!P:P,0)} -> #NAME? | Q17: =_xludf.XLOOKUP($D17,#REF!,#REF!,0) -> #NAME? | R17: {=_xludf.XLOOKUP(D17,'KPS #48'!D:D,'KPS #48'!R:R,0)} -> #NAME? | S17: =_xludf.XLOOKUP($D17,#REF!,#REF!,0) -> #NAME? | T17: {=_xludf.XLOOKUP(D17,'KPS #48'!D:D,'KPS #48'!T:T,0)} -> #NAME? | U17: =_xludf.XLOOKUP($D17,#REF!,#REF!,0) -> #NAME? | V17: {=_xludf.XLOOKUP(D17,'KPS #48'!D:D,'KPS #48'!V:V,0)} -> #NAME? | W17: =_xludf.XLOOKUP($D17,#REF!,#REF!,0) -> #NAME? | X17: =SUM(V17,T17,R17,P17,N17,L17,J17) -> #NAME? | Y17: =SUM(W17,U17,S17,Q17,O17,M17,K17) -> #NAME? | AA17: =X17*IFERROR(VLOOKUP(D17,'Brand List'!$B:$D,3,0),0) -> #NAME? | AB17: =H17*IFERROR(VLOOKUP(D17,'Brand List'!$B:$D,3,0),0) -> #NAME? | AC17: =AA17-AB17 -> #NAME? | AD17: =_xlfn.XLOOKUP(D17,[1]Summary!$E:$E,[1]Summary!$L:$L,0) -> 0 | AE17: =AD17*X17 -> #NAME?
A18: =D18 -> VGZ16 | B18: PR Sejahtera Abadi | C18: SKM LT 16 | D18: VGZ16 | E18: Vegaz Lt 16S | F18: Malvin | Andry | G18: {=_xludf.XLOOKUP(D18,'KPS #48'!D:D,'KPS #48'!G:G,0)} -> #NAME? | H18: {=_xludf.XLOOKUP(D18,'KPS #48'!D:D,'KPS #48'!H:H,0)} -> #NAME? | I18: =IF(AND(H18=0,G18=0),"No Delivery",IF(COUNTA(J18,L18,N18,P18,R18,T18,V18)=1,"Delivery",IF(COUNTA(J18,L18,N18,P18,R18,T18,V18)>1,"Partial Delivery",IF(COUNTA(J18,L18,N18,P18,R18,T18,V18)=0,"Will be Updated")))) -> #NAME? | J18: {=_xludf.XLOOKUP(D18,'KPS #48'!D:D,'KPS #48'!J:J,0)} -> #NAME? | K18: =_xludf.XLOOKUP($D18,#REF!,#REF!,0) -> #NAME? | L18: {=_xludf.XLOOKUP(D18,'KPS #48'!D:D,'KPS #48'!L:L,0)} -> #NAME? | M18: =_xludf.XLOOKUP($D18,#REF!,#REF!,0) -> #NAME? | N18: {=_xludf.XLOOKUP(D18,'KPS #48'!D:D,'KPS #48'!N:N,0)} -> #NAME? | O18: =_xludf.XLOOKUP($D18,#REF!,#REF!,0) -> #NAME? | P18: {=_xludf.XLOOKUP(D18,'KPS #48'!D:D,'KPS #48'!P:P,0)} -> #NAME? | Q18: =_xludf.XLOOKUP($D18,#REF!,#REF!,0) -> #NAME? | R18: {=_xludf.XLOOKUP(D18,'KPS #48'!D:D,'KPS #48'!R:R,0)} -> #NAME? | S18: =_xludf.XLOOKUP($D18,#REF!,#REF!,0) -> #NAME? | T18: {=_xludf.XLOOKUP(D18,'KPS #48'!D:D,'KPS #48'!T:T,0)} -> #NAME? | U18: =_xludf.XLOOKUP($D18,#REF!,#REF!,0) -> #NAME? | V18: {=_xludf.XLOOKUP(D18,'KPS #48'!D:D,'KPS #48'!V:V,0)} -> #NAME? | W18: =_xludf.XLOOKUP($D18,#REF!,#REF!,0) -> #NAME? | X18: =SUM(V18,T18,R18,P18,N18,L18,J18) -> #NAME? | Y18: =SUM(W18,U18,S18,Q18,O18,M18,K18) -> #NAME? | Z18: GR Shift 3 | AA18: =X18*IFERROR(VLOOKUP(D18,'Brand List'!$B:$D,3,0),0) -> #NAME? | AB18: =H18*IFERROR(VLOOKUP(D18,'Brand List'!$B:$D,3,0),0) -> #NAME? | AC18: =AA18-AB18 -> #NAME? | AD18: =_xlfn.XLOOKUP(D18,[1]Summary!$E:$E,[1]Summary!$L:$L,0) -> 0 | AE18: =AD18*X18 -> #NAME?
B19: PR Sejahtera Abadi | C19: SKM HT 12 | D19: BLS12 | E19: Balai Emas SKM HT 12S | F19: Malvin | Andry | G19: {=_xludf.XLOOKUP(D19,'KPS #48'!D:D,'KPS #48'!G:G,0)} -> #NAME? | H19: {=_xludf.XLOOKUP(D19,'KPS #48'!D:D,'KPS #48'!H:H,0)} -> #NAME? | I19: =IF(AND(H19=0,G19=0),"No Delivery",IF(COUNTA(J19,L19,N19,P19,R19,T19,V19)=1,"Delivery",IF(COUNTA(J19,L19,N19,P19,R19,T19,V19)>1,"Partial Delivery",IF(COUNTA(J19,L19,N19,P19,R19,T19,V19)=0,"Will be Updated")))) -> #NAME? | J19: {=_xludf.XLOOKUP(D19,'KPS #48'!D:D,'KPS #48'!J:J,0)} -> #NAME? | K19: =_xludf.XLOOKUP($D19,#REF!,#REF!,0) -> #NAME? | L19: {=_xludf.XLOOKUP(D19,'KPS #48'!D:D,'KPS #48'!L:L,0)} -> #NAME? | M19: =_xludf.XLOOKUP($D19,#REF!,#REF!,0) -> #NAME? | N19: {=_xludf.XLOOKUP(D19,'KPS #48'!D:D,'KPS #48'!N:N,0)} -> #NAME? | O19: =_xludf.XLOOKUP($D19,#REF!,#REF!,0) -> #NAME? | P19: {=_xludf.XLOOKUP(D19,'KPS #48'!D:D,'KPS #48'!P:P,0)} -> #NAME? | Q19: =_xludf.XLOOKUP($D19,#REF!,#REF!,0) -> #NAME? | R19: {=_xludf.XLOOKUP(D19,'KPS #48'!D:D,'KPS #48'!R:R,0)} -> #NAME? | S19: =_xludf.XLOOKUP($D19,#REF!,#REF!,0) -> #NAME? | T19: {=_xludf.XLOOKUP(D19,'KPS #48'!D:D,'KPS #48'!T:T,0)} -> #NAME? | U19: =_xludf.XLOOKUP($D19,#REF!,#REF!,0) -> #NAME? | V19: {=_xludf.XLOOKUP(D19,'KPS #48'!D:D,'KPS #48'!V:V,0)} -> #NAME? | W19: =_xludf.XLOOKUP($D19,#REF!,#REF!,0) -> #NAME? | X19: =SUM(V19,T19,R19,P19,N19,L19,J19) -> #NAME? | Y19: =SUM(W19,U19,S19,Q19,O19,M19,K19) -> #NAME? | AA19: =X19*IFERROR(VLOOKUP(D19,'Brand List'!$B:$D,3,0),0) -> #NAME? | AB19: =H19*IFERROR(VLOOKUP(D19,'Brand List'!$B:$D,3,0),0) -> #NAME? | AC19: =AA19-AB19 -> #NAME? | AD19: =_xlfn.XLOOKUP(D19,[1]Summary!$E:$E,[1]Summary!$L:$L,0) -> 0 | AE19: =AD19*X19 -> #NAME?
A20: =D20 -> ARM12 | B20: PT Bathara Sejahtera Abadi | C20: SKM HT 12 | D20: ARM12 | E20: Ares Mind Skm Ht 12S | F20: Malvin | Andry | G20: {=_xludf.XLOOKUP(D20,'KPS #48'!D:D,'KPS #48'!G:G,0)} -> #NAME? | H20: {=_xludf.XLOOKUP(D20,'KPS #48'!D:D,'KPS #48'!H:H,0)} -> #NAME? | I20: =IF(AND(H20=0,G20=0),"No Delivery",IF(COUNTA(J20,L20,N20,P20,R20,T20,V20)=1,"Delivery",IF(COUNTA(J20,L20,N20,P20,R20,T20,V20)>1,"Partial Delivery",IF(COUNTA(J20,L20,N20,P20,R20,T20,V20)=0,"Will be Updated")))) -> #NAME? | J20: {=_xludf.XLOOKUP(D20,'KPS #48'!D:D,'KPS #48'!J:J,0)} -> #NAME? | K20: =_xludf.XLOOKUP($D20,#REF!,#REF!,0) -> #NAME? | L20: {=_xludf.XLOOKUP(D20,'KPS #48'!D:D,'KPS #48'!L:L,0)} -> #NAME? | M20: =_xludf.XLOOKUP($D20,#REF!,#REF!,0) -> #NAME? | N20: {=_xludf.XLOOKUP(D20,'KPS #48'!D:D,'KPS #48'!N:N,0)} -> #NAME? | O20: =_xludf.XLOOKUP($D20,#REF!,#REF!,0) -> #NAME? | P20: {=_xludf.XLOOKUP(D20,'KPS #48'!D:D,'KPS #48'!P:P,0)} -> #NAME? | Q20: =_xludf.XLOOKUP($D20,#REF!,#REF!,0) -> #NAME? | R20: {=_xludf.XLOOKUP(D20,'KPS #48'!D:D,'KPS #48'!R:R,0)} -> #NAME? | S20: =_xludf.XLOOKUP($D20,#REF!,#REF!,0) -> #NAME? | T20: {=_xludf.XLOOKUP(D20,'KPS #48'!D:D,'KPS #48'!T:T,0)} -> #NAME? | U20: =_xludf.XLOOKUP($D20,#REF!,#REF!,0) -> #NAME? | V20: {=_xludf.XLOOKUP(D20,'KPS #48'!D:D,'KPS #48'!V:V,0)} -> #NAME? | W20: =_xludf.XLOOKUP($D20,#REF!,#REF!,0) -> #NAME? | X20: =SUM(V20,T20,R20,P20,N20,L20,J20) -> #NAME? | Y20: =SUM(W20,U20,S20,Q20,O20,M20,K20) -> #NAME? | AA20: =X20*IFERROR(VLOOKUP(D20,'Brand List'!$B:$D,3,0),0) -> #NAME? | AB20: =H20*IFERROR(VLOOKUP(D20,'Brand List'!$B:$D,3,0),0) -> #NAME? | AC20: =AA20-AB20 -> #NAME? | AD20: =_xlfn.XLOOKUP(D20,[1]Summary!$E:$E,[1]Summary!$L:$L,0) -> 0 | AE20: =AD20*X20 -> #NAME?
A21: =D21 -> ARM16 | B21: PT Bathara Sejahtera Abadi | C21: SKM HT 16 | D21: ARM16 | E21: Ares Mind Skm Ht 16S | F21: Malvin | Andry | G21: {=_xludf.XLOOKUP(D21,'KPS #48'!D:D,'KPS #48'!G:G,0)} -> #NAME? | H21: {=_xludf.XLOOKUP(D21,'KPS #48'!D:D,'KPS #48'!H:H,0)} -> #NAME? | I21: =IF(AND(H21=0,G21=0),"No Delivery",IF(COUNTA(J21,L21,N21,P21,R21,T21,V21)=1,"Delivery",IF(COUNTA(J21,L21,N21,P21,R21,T21,V21)>1,"Partial Delivery",IF(COUNTA(J21,L21,N21,P21,R21,T21,V21)=0,"Will be Updated")))) -> #NAME? | J21: {=_xludf.XLOOKUP(D21,'KPS #48'!D:D,'KPS #48'!J:J,0)} -> #NAME? | K21: =_xludf.XLOOKUP($D21,#REF!,#REF!,0) -> #NAME? | L21: {=_xludf.XLOOKUP(D21,'KPS #48'!D:D,'KPS #48'!L:L,0)} -> #NAME? | M21: =_xludf.XLOOKUP($D21,#REF!,#REF!,0) -> #NAME? | N21: {=_xludf.XLOOKUP(D21,'KPS #48'!D:D,'KPS #48'!N:N,0)} -> #NAME? | O21: =_xludf.XLOOKUP($D21,#REF!,#REF!,0) -> #NAME? | P21: {=_xludf.XLOOKUP(D21,'KPS #48'!D:D,'KPS #48'!P:P,0)} -> #NAME? | Q21: =_xludf.XLOOKUP($D21,#REF!,#REF!,0) -> #NAME? | R21: {=_xludf.XLOOKUP(D21,'KPS #48'!D:D,'KPS #48'!R:R,0)} -> #NAME? | S21: =_xludf.XLOOKUP($D21,#REF!,#REF!,0) -> #NAME? | T21: {=_xludf.XLOOKUP(D21,'KPS #48'!D:D,'KPS #48'!T:T,0)} -> #NAME? | U21: =_xludf.XLOOKUP($D21,#REF!,#REF!,0) -> #NAME? | V21: {=_xludf.XLOOKUP(D21,'KPS #48'!D:D,'KPS #48'!V:V,0)} -> #NAME? | W21: =_xludf.XLOOKUP($D21,#REF!,#REF!,0) -> #NAME? | X21: =SUM(V21,T21,R21,P21,N21,L21,J21) -> #NAME? | Y21: =SUM(W21,U21,S21,Q21,O21,M21,K21) -> #NAME? | AA21: =X21*IFERROR(VLOOKUP(D21,'Brand List'!$B:$D,3,0),0) -> #NAME? | AB21: =H21*IFERROR(VLOOKUP(D21,'Brand List'!$B:$D,3,0),0) -> #NAME? | AC21: =AA21-AB21 -> #NAME? | AD21: =_xlfn.XLOOKUP(D21,[1]Summary!$E:$E,[1]Summary!$L:$L,0) -> 0 | AE21: =AD21*X21 -> #NAME?
A22: =D22 -> ARK12 | B22: PT Bathara Sejahtera Abadi | C22: SKM HT 12 | D22: ARK12 | E22: Ares Kaizer Skm Ht 12S | F22: Malvin | Andry | G22: {=_xludf.XLOOKUP(D22,'KPS #48'!D:D,'KPS #48'!G:G,0)} -> #NAME? | H22: {=_xludf.XLOOKUP(D22,'KPS #48'!D:D,'KPS #48'!H:H,0)} -> #NAME? | I22: =IF(AND(H22=0,G22=0),"No Delivery",IF(COUNTA(J22,L22,N22,P22,R22,T22,V22)=1,"Delivery",IF(COUNTA(J22,L22,N22,P22,R22,T22,V22)>1,"Partial Delivery",IF(COUNTA(J22,L22,N22,P22,R22,T22,V22)=0,"Will be Updated")))) -> #NAME? | J22: {=_xludf.XLOOKUP(D22,'KPS #48'!D:D,'KPS #48'!J:J,0)} -> #NAME? | K22: =_xludf.XLOOKUP($D22,#REF!,#REF!,0) -> #NAME? | L22: {=_xludf.XLOOKUP(D22,'KPS #48'!D:D,'KPS #48'!L:L,0)} -> #NAME? | M22: =_xludf.XLOOKUP($D22,#REF!,#REF!,0) -> #NAME? | N22: {=_xludf.XLOOKUP(D22,'KPS #48'!D:D,'KPS #48'!N:N,0)} -> #NAME? | O22: =_xludf.XLOOKUP($D22,#REF!,#REF!,0) -> #NAME? | P22: {=_xludf.XLOOKUP(D22,'KPS #48'!D:D,'KPS #48'!P:P,0)} -> #NAME? | Q22: =_xludf.XLOOKUP($D22,#REF!,#REF!,0) -> #NAME? | R22: {=_xludf.XLOOKUP(D22,'KPS #48'!D:D,'KPS #48'!R:R,0)} -> #NAME? | S22: =_xludf.XLOOKUP($D22,#REF!,#REF!,0) -> #NAME? | T22: {=_xludf.XLOOKUP(D22,'KPS #48'!D:D,'KPS #48'!T:T,0)} -> #NAME? | U22: =_xludf.XLOOKUP($D22,#REF!,#REF!,0) -> #NAME? | V22: {=_xludf.XLOOKUP(D22,'KPS #48'!D:D,'KPS #48'!V:V,0)} -> #NAME? | W22: =_xludf.XLOOKUP($D22,#REF!,#REF!,0) -> #NAME? | X22: =SUM(V22,T22,R22,P22,N22,L22,J22) -> #NAME? | Y22: =SUM(W22,U22,S22,Q22,O22,M22,K22) -> #NAME? | AA22: =X22*IFERROR(VLOOKUP(D22,'Brand List'!$B:$D,3,0),0) -> #NAME? | AB22: =H22*IFERROR(VLOOKUP(D22,'Brand List'!$B:$D,3,0),0) -> #NAME? | AC22: =AA22-AB22 -> #NAME? | AD22: =_xlfn.XLOOKUP(D22,[1]Summary!$E:$E,[1]Summary!$L:$L,0) -> 0 | AE22: =AD22*X22 -> #NAME?
A23: =D23 -> ARB12 | B23: PT Bathara Sejahtera Abadi | C23: SKM HT 12 | D23: ARB12 | E23: Ares Bold Skm Ht 12S | F23: Malvin | Andry | G23: {=_xludf.XLOOKUP(D23,'KPS #48'!D:D,'KPS #48'!G:G,0)} -> #NAME? | H23: {=_xludf.XLOOKUP(D23,'KPS #48'!D:D,'KPS #48'!H:H,0)} -> #NAME? | I23: =IF(AND(H23=0,G23=0),"No Delivery",IF(COUNTA(J23,L23,N23,P23,R23,T23,V23)=1,"Delivery",IF(COUNTA(J23,L23,N23,P23,R23,T23,V23)>1,"Partial Delivery",IF(COUNTA(J23,L23,N23,P23,R23,T23,V23)=0,"Will be Updated")))) -> #NAME? | J23: {=_xludf.XLOOKUP(D23,'KPS #48'!D:D,'KPS #48'!J:J,0)} -> #NAME? | K23: =_xludf.XLOOKUP($D23,#REF!,#REF!,0) -> #NAME? | L23: {=_xludf.XLOOKUP(D23,'KPS #48'!D:D,'KPS #48'!L:L,0)} -> #NAME? | M23: =_xludf.XLOOKUP($D23,#REF!,#REF!,0) -> #NAME? | N23: {=_xludf.XLOOKUP(D23,'KPS #48'!D:D,'KPS #48'!N:N,0)} -> #NAME? | O23: =_xludf.XLOOKUP($D23,#REF!,#REF!,0) -> #NAME? | P23: {=_xludf.XLOOKUP(D23,'KPS #48'!D:D,'KPS #48'!P:P,0)} -> #NAME? | Q23: =_xludf.XLOOKUP($D23,#REF!,#REF!,0) -> #NAME? | R23: {=_xludf.XLOOKUP(D23,'KPS #48'!D:D,'KPS #48'!R:R,0)} -> #NAME? | S23: =_xludf.XLOOKUP($D23,#REF!,#REF!,0) -> #NAME? | T23: {=_xludf.XLOOKUP(D23,'KPS #48'!D:D,'KPS #48'!T:T,0)} -> #NAME? | U23: =_xludf.XLOOKUP($D23,#REF!,#REF!,0) -> #NAME? | V23: {=_xludf.XLOOKUP(D23,'KPS #48'!D:D,'KPS #48'!V:V,0)} -> #NAME? | W23: =_xludf.XLOOKUP($D23,#REF!,#REF!,0) -> #NAME? | X23: =SUM(V23,T23,R23,P23,N23,L23,J23) -> #NAME? | Y23: =SUM(W23,U23,S23,Q23,O23,M23,K23) -> #NAME? | Z23: GR Shift 3 | AA23: =X23*IFERROR(VLOOKUP(D23,'Brand List'!$B:$D,3,0),0) -> #NAME? | AB23: =H23*IFERROR(VLOOKUP(D23,'Brand List'!$B:$D,3,0),0) -> #NAME? | AC23: =AA23-AB23 -> #NAME? | AD23: =_xlfn.XLOOKUP(D23,[1]Summary!$E:$E,[1]Summary!$L:$L,0) -> 0 | AE23: =AD23*X23 -> #NAME?
A24: =D24 -> ARB20 | B24: PT Bathara Sejahtera Abadi | C24: SKM HT 20 | D24: ARB20 | E24: Ares Bold Skm Ht 20S | F24: Malvin | Andry | G24: {=_xludf.XLOOKUP(D24,'KPS #48'!D:D,'KPS #48'!G:G,0)} -> #NAME? | H24: {=_xludf.XLOOKUP(D24,'KPS #48'!D:D,'KPS #48'!H:H,0)} -> #NAME? | I24: =IF(AND(H24=0,G24=0),"No Delivery",IF(COUNTA(J24,L24,N24,P24,R24,T24,V24)=1,"Delivery",IF(COUNTA(J24,L24,N24,P24,R24,T24,V24)>1,"Partial Delivery",IF(COUNTA(J24,L24,N24,P24,R24,T24,V24)=0,"Will be Updated")))) -> #NAME? | J24: {=_xludf.XLOOKUP(D24,'KPS #48'!D:D,'KPS #48'!J:J,0)} -> #NAME? | K24: =_xludf.XLOOKUP($D24,#REF!,#REF!,0) -> #NAME? | L24: {=_xludf.XLOOKUP(D24,'KPS #48'!D:D,'KPS #48'!L:L,0)} -> #NAME? | M24: =_xludf.XLOOKUP($D24,#REF!,#REF!,0) -> #NAME? | N24: {=_xludf.XLOOKUP(D24,'KPS #48'!D:D,'KPS #48'!N:N,0)} -> #NAME? | O24: =_xludf.XLOOKUP($D24,#REF!,#REF!,0) -> #NAME? | P24: {=_xludf.XLOOKUP(D24,'KPS #48'!D:D,'KPS #48'!P:P,0)} -> #NAME? | Q24: =_xludf.XLOOKUP($D24,#REF!,#REF!,0) -> #NAME? | R24: {=_xludf.XLOOKUP(D24,'KPS #48'!D:D,'KPS #48'!R:R,0)} -> #NAME? | S24: =_xludf.XLOOKUP($D24,#REF!,#REF!,0) -> #NAME? | T24: {=_xludf.XLOOKUP(D24,'KPS #48'!D:D,'KPS #48'!T:T,0)} -> #NAME? | U24: =_xludf.XLOOKUP($D24,#REF!,#REF!,0) -> #NAME? | V24: {=_xludf.XLOOKUP(D24,'KPS #48'!D:D,'KPS #48'!V:V,0)} -> #NAME? | W24: =_xludf.XLOOKUP($D24,#REF!,#REF!,0) -> #NAME? | X24: =SUM(V24,T24,R24,P24,N24,L24,J24) -> #NAME? | Y24: =SUM(W24,U24,S24,Q24,O24,M24,K24) -> #NAME? | Z24: GR Shift 3 | AA24: =X24*IFERROR(VLOOKUP(D24,'Brand List'!$B:$D,3,0),0) -> #NAME? | AB24: =H24*IFERROR(VLOOKUP(D24,'Brand List'!$B:$D,3,0),0) -> #NAME? | AC24: =AA24-AB24 -> #NAME? | AD24: =_xlfn.XLOOKUP(D24,[1]Summary!$E:$E,[1]Summary!$L:$L,0) -> 0 | AE24: =AD24*X24 -> #NAME?
A25: =D25 -> ARL16 | B25: PT Bathara Sejahtera Abadi | C25: SKM LT 16 | D25: ARL16 | E25: Ares Lite Skm 16S | F25: Malvin | Andry | G25: {=_xludf.XLOOKUP(D25,'KPS #48'!D:D,'KPS #48'!G:G,0)} -> #NAME? | H25: {=_xludf.XLOOKUP(D25,'KPS #48'!D:D,'KPS #48'!H:H,0)} -> #NAME? | I25: =IF(AND(H25=0,G25=0),"No Delivery",IF(COUNTA(J25,L25,N25,P25,R25,T25,V25)=1,"Delivery",IF(COUNTA(J25,L25,N25,P25,R25,T25,V25)>1,"Partial Delivery",IF(COUNTA(J25,L25,N25,P25,R25,T25,V25)=0,"Will be Updated")))) -> #NAME? | J25: {=_xludf.XLOOKUP(D25,'KPS #48'!D:D,'KPS #48'!J:J,0)} -> #NAME? | K25: =_xludf.XLOOKUP($D25,#REF!,#REF!,0) -> #NAME? | L25: {=_xludf.XLOOKUP(D25,'KPS #48'!D:D,'KPS #48'!L:L,0)} -> #NAME? | M25: =_xludf.XLOOKUP($D25,#REF!,#REF!,0) -> #NAME? | N25: {=_xludf.XLOOKUP(D25,'KPS #48'!D:D,'KPS #48'!N:N,0)} -> #NAME? | O25: =_xludf.XLOOKUP($D25,#REF!,#REF!,0) -> #NAME? | P25: {=_xludf.XLOOKUP(D25,'KPS #48'!D:D,'KPS #48'!P:P,0)} -> #NAME? | Q25: =_xludf.XLOOKUP($D25,#REF!,#REF!,0) -> #NAME? | R25: {=_xludf.XLOOKUP(D25,'KPS #48'!D:D,'KPS #48'!R:R,0)} -> #NAME? | S25: =_xludf.XLOOKUP($D25,#REF!,#REF!,0) -> #NAME? | T25: {=_xludf.XLOOKUP(D25,'KPS #48'!D:D,'KPS #48'!T:T,0)} -> #NAME? | U25: =_xludf.XLOOKUP($D25,#REF!,#REF!,0) -> #NAME? | V25: {=_xludf.XLOOKUP(D25,'KPS #48'!D:D,'KPS #48'!V:V,0)} -> #NAME? | W25: =_xludf.XLOOKUP($D25,#REF!,#REF!,0) -> #NAME? | X25: =SUM(V25,T25,R25,P25,N25,L25,J25) -> #NAME? | Y25: =SUM(W25,U25,S25,Q25,O25,M25,K25) -> #NAME? | AA25: =X25*IFERROR(VLOOKUP(D25,'Brand List'!$B:$D,3,0),0) -> #NAME? | AB25: =H25*IFERROR(VLOOKUP(D25,'Brand List'!$B:$D,3,0),0) -> #NAME? | AC25: =AA25-AB25 -> #NAME? | AD25: =_xlfn.XLOOKUP(D25,[1]Summary!$E:$E,[1]Summary!$L:$L,0) -> 0 | AE25: =AD25*X25 -> #NAME?
A26: =D26 -> BRW12 | B26: PT Alam Raya Amerta Subur Makmur | C26: SKT 12 | D26: BRW12 | E26: Birawa Skt 12S | F26: Edward | Andry | G26: {=_xludf.XLOOKUP(D26,'KPS #48'!D:D,'KPS #48'!G:G,0)} -> #NAME? | H26: {=_xludf.XLOOKUP(D26,'KPS #48'!D:D,'KPS #48'!H:H,0)} -> #NAME? | I26: =IF(AND(H26=0,G26=0),"No Delivery",IF(COUNTA(J26,L26,N26,P26,R26,T26,V26)=1,"Delivery",IF(COUNTA(J26,L26,N26,P26,R26,T26,V26)>1,"Partial Delivery",IF(COUNTA(J26,L26,N26,P26,R26,T26,V26)=0,"Will be Updated")))) -> #NAME? | J26: {=_xludf.XLOOKUP(D26,'KPS #48'!D:D,'KPS #48'!J:J,0)} -> #NAME? | K26: =_xludf.XLOOKUP($D26,#REF!,#REF!,0) -> #NAME? | L26: {=_xludf.XLOOKUP(D26,'KPS #48'!D:D,'KPS #48'!L:L,0)} -> #NAME? | M26: =_xludf.XLOOKUP($D26,#REF!,#REF!,0) -> #NAME? | N26: {=_xludf.XLOOKUP(D26,'KPS #48'!D:D,'KPS #48'!N:N,0)} -> #NAME? | O26: =_xludf.XLOOKUP($D26,#REF!,#REF!,0) -> #NAME? | P26: {=_xludf.XLOOKUP(D26,'KPS #48'!D:D,'KPS #48'!P:P,0)} -> #NAME? | Q26: =_xludf.XLOOKUP($D26,#REF!,#REF!,0) -> #NAME? | R26: {=_xludf.XLOOKUP(D26,'KPS #48'!D:D,'KPS #48'!R:R,0)} -> #NAME? | S26: =_xludf.XLOOKUP($D26,#REF!,#REF!,0) -> #NAME? | T26: {=_xludf.XLOOKUP(D26,'KPS #48'!D:D,'KPS #48'!T:T,0)} -> #NAME? | U26: =_xludf.XLOOKUP($D26,#REF!,#REF!,0) -> #NAME? | V26: {=_xludf.XLOOKUP(D26,'KPS #48'!D:D,'KPS #48'!V:V,0)} -> #NAME? | W26: =_xludf.XLOOKUP($D26,#REF!,#REF!,0) -> #NAME? | X26: =SUM(V26,T26,R26,P26,N26,L26,J26) -> #NAME? | Y26: =SUM(W26,U26,S26,Q26,O26,M26,K26) -> #NAME? | AA26: =X26*IFERROR(VLOOKUP(D26,'Brand List'!$B:$D,3,0),0) -> #NAME? | AB26: =H26*IFERROR(VLOOKUP(D26,'Brand List'!$B:$D,3,0),0) -> #NAME? | AC26: =AA26-AB26 -> #NAME? | AD26: =_xlfn.XLOOKUP(D26,[1]Summary!$E:$E,[1]Summary!$L:$L,0) -> 0 | AE26: =AD26*X26 -> #NAME?
A27: =D27 -> SRS12 | B27: PT Artha Jaya | C27: SKT 12 | D27: SRS12 | E27: Serasa Skt 12S | F27: Edward | Andry | G27: {=_xludf.XLOOKUP(D27,'KPS #48'!D:D,'KPS #48'!G:G,0)} -> #NAME? | H27: {=_xludf.XLOOKUP(D27,'KPS #48'!D:D,'KPS #48'!H:H,0)} -> #NAME? | I27: =IF(AND(H27=0,G27=0),"No Delivery",IF(COUNTA(J27,L27,N27,P27,R27,T27,V27)=1,"Delivery",IF(COUNTA(J27,L27,N27,P27,R27,T27,V27)>1,"Partial Delivery",IF(COUNTA(J27,L27,N27,P27,R27,T27,V27)=0,"Will be Updated")))) -> #NAME? | J27: {=_xludf.XLOOKUP(D27,'KPS #48'!D:D,'KPS #48'!J:J,0)} -> #NAME? | K27: =_xludf.XLOOKUP($D27,#REF!,#REF!,0) -> #NAME? | L27: {=_xludf.XLOOKUP(D27,'KPS #48'!D:D,'KPS #48'!L:L,0)} -> #NAME? | M27: =_xludf.XLOOKUP($D27,#REF!,#REF!,0) -> #NAME? | N27: {=_xludf.XLOOKUP(D27,'KPS #48'!D:D,'KPS #48'!N:N,0)} -> #NAME? | O27: =_xludf.XLOOKUP($D27,#REF!,#REF!,0) -> #NAME? | P27: {=_xludf.XLOOKUP(D27,'KPS #48'!D:D,'KPS #48'!P:P,0)} -> #NAME? | Q27: =_xludf.XLOOKUP($D27,#REF!,#REF!,0) -> #NAME? | R27: {=_xludf.XLOOKUP(D27,'KPS #48'!D:D,'KPS #48'!R:R,0)} -> #NAME? | S27: =_xludf.XLOOKUP($D27,#REF!,#REF!,0) -> #NAME? | T27: {=_xludf.XLOOKUP(D27,'KPS #48'!D:D,'KPS #48'!T:T,0)} -> #NAME? | U27: =_xludf.XLOOKUP($D27,#REF!,#REF!,0) -> #NAME? | V27: {=_xludf.XLOOKUP(D27,'KPS #48'!D:D,'KPS #48'!V:V,0)} -> #NAME? | W27: =_xludf.XLOOKUP($D27,#REF!,#REF!,0) -> #NAME? | X27: =SUM(V27,T27,R27,P27,N27,L27,J27) -> #NAME? | Y27: =SUM(W27,U27,S27,Q27,O27,M27,K27) -> #NAME? | Z27: 50 box po kps 46 to be confirm | AA27: =X27*IFERROR(VLOOKUP(D27,'Brand List'!$B:$D,3,0),0) -> #NAME? | AB27: =H27*IFERROR(VLOOKUP(D27,'Brand List'!$B:$D,3,0),0) -> #NAME? | AC27: =AA27-AB27 -> #NAME? | AD27: =_xlfn.XLOOKUP(D27,[1]Summary!$E:$E,[1]Summary!$L:$L,0) -> 0 | AE27: =AD27*X27 -> #NAME?
A28: =D28 -> SRS16 | B28: PT Artha Jaya | C28: SKT 16 | D28: SRS16 | E28: Serasa Skt 16S | F28: Edward | Andry | G28: {=_xludf.XLOOKUP(D28,'KPS #48'!D:D,'KPS #48'!G:G,0)} -> #NAME? | H28: {=_xludf.XLOOKUP(D28,'KPS #48'!D:D,'KPS #48'!H:H,0)} -> #NAME? | I28: =IF(AND(H28=0,G28=0),"No Delivery",IF(COUNTA(J28,L28,N28,P28,R28,T28,V28)=1,"Delivery",IF(COUNTA(J28,L28,N28,P28,R28,T28,V28)>1,"Partial Delivery",IF(COUNTA(J28,L28,N28,P28,R28,T28,V28)=0,"Will be Updated")))) -> #NAME? | J28: {=_xludf.XLOOKUP(D28,'KPS #48'!D:D,'KPS #48'!J:J,0)} -> #NAME? | K28: =_xludf.XLOOKUP($D28,#REF!,#REF!,0) -> #NAME? | L28: {=_xludf.XLOOKUP(D28,'KPS #48'!D:D,'KPS #48'!L:L,0)} -> #NAME? | M28: =_xludf.XLOOKUP($D28,#REF!,#REF!,0) -> #NAME? | N28: {=_xludf.XLOOKUP(D28,'KPS #48'!D:D,'KPS #48'!N:N,0)} -> #NAME? | O28: =_xludf.XLOOKUP($D28,#REF!,#REF!,0) -> #NAME? | P28: {=_xludf.XLOOKUP(D28,'KPS #48'!D:D,'KPS #48'!P:P,0)} -> #NAME? | Q28: =_xludf.XLOOKUP($D28,#REF!,#REF!,0) -> #NAME? | R28: {=_xludf.XLOOKUP(D28,'KPS #48'!D:D,'KPS #48'!R:R,0)} -> #NAME? | S28: =_xludf.XLOOKUP($D28,#REF!,#REF!,0) -> #NAME? | T28: {=_xludf.XLOOKUP(D28,'KPS #48'!D:D,'KPS #48'!T:T,0)} -> #NAME? | U28: =_xludf.XLOOKUP($D28,#REF!,#REF!,0) -> #NAME? | V28: {=_xludf.XLOOKUP(D28,'KPS #48'!D:D,'KPS #48'!V:V,0)} -> #NAME? | W28: =_xludf.XLOOKUP($D28,#REF!,#REF!,0) -> #NAME? | X28: =SUM(V28,T28,R28,P28,N28,L28,J28) -> #NAME? | Y28: =SUM(W28,U28,S28,Q28,O28,M28,K28) -> #NAME? | Z28: Remaining outstand 150 box po kps 45 | AA28: =X28*IFERROR(VLOOKUP(D28,'Brand List'!$B:$D,3,0),0) -> #NAME? | AB28: =H28*IFERROR(VLOOKUP(D28,'Brand List'!$B:$D,3,0),0) -> #NAME? | AC28: =AA28-AB28 -> #NAME? | AD28: =_xlfn.XLOOKUP(D28,[1]Summary!$E:$E,[1]Summary!$L:$L,0) -> 0 | AE28: =AD28*X28 -> #NAME?
A29: =D29 -> POS16 | B29: PT Artha Jaya | C29: SKM LT 16 | D29: POS16 | E29: Post X Skm Lt16S | F29: Edward | Andry | G29: {=_xludf.XLOOKUP(D29,'KPS #48'!D:D,'KPS #48'!G:G,0)} -> #NAME? | H29: {=_xludf.XLOOKUP(D29,'KPS #48'!D:D,'KPS #48'!H:H,0)} -> #NAME? | I29: =IF(AND(H29=0,G29=0),"No Delivery",IF(COUNTA(J29,L29,N29,P29,R29,T29,V29)=1,"Delivery",IF(COUNTA(J29,L29,N29,P29,R29,T29,V29)>1,"Partial Delivery",IF(COUNTA(J29,L29,N29,P29,R29,T29,V29)=0,"Will be Updated")))) -> #NAME? | J29: {=_xludf.XLOOKUP(D29,'KPS #48'!D:D,'KPS #48'!J:J,0)} -> #NAME? | K29: =_xludf.XLOOKUP($D29,#REF!,#REF!,0) -> #NAME? | L29: {=_xludf.XLOOKUP(D29,'KPS #48'!D:D,'KPS #48'!L:L,0)} -> #NAME? | M29: =_xludf.XLOOKUP($D29,#REF!,#REF!,0) -> #NAME? | N29: {=_xludf.XLOOKUP(D29,'KPS #48'!D:D,'KPS #48'!N:N,0)} -> #NAME? | O29: =_xludf.XLOOKUP($D29,#REF!,#REF!,0) -> #NAME? | P29: {=_xludf.XLOOKUP(D29,'KPS #48'!D:D,'KPS #48'!P:P,0)} -> #NAME? | Q29: =_xludf.XLOOKUP($D29,#REF!,#REF!,0) -> #NAME? | R29: {=_xludf.XLOOKUP(D29,'KPS #48'!D:D,'KPS #48'!R:R,0)} -> #NAME? | S29: =_xludf.XLOOKUP($D29,#REF!,#REF!,0) -> #NAME? | T29: {=_xludf.XLOOKUP(D29,'KPS #48'!D:D,'KPS #48'!T:T,0)} -> #NAME? | U29: =_xludf.XLOOKUP($D29,#REF!,#REF!,0) -> #NAME? | V29: {=_xludf.XLOOKUP(D29,'KPS #48'!D:D,'KPS #48'!V:V,0)} -> #NAME? | W29: =_xludf.XLOOKUP($D29,#REF!,#REF!,0) -> #NAME? | X29: =SUM(V29,T29,R29,P29,N29,L29,J29) -> #NAME? | Y29: =SUM(W29,U29,S29,Q29,O29,M29,K29) -> #NAME? | AA29: =X29*IFERROR(VLOOKUP(D29,'Brand List'!$B:$D,3,0),0) -> #NAME? | AB29: =H29*IFERROR(VLOOKUP(D29,'Brand List'!$B:$D,3,0),0) -> #NAME? | AC29: =AA29-AB29 -> #NAME? | AD29: =_xlfn.XLOOKUP(D29,[1]Summary!$E:$E,[1]Summary!$L:$L,0) -> 0 | AE29: =AD29*X29 -> #NAME?
A30: =D30 -> TTL16 | B30: PT Artha Jaya | C30: SKM LT 16 | D30: TTL16 | E30: Total Skm Lt16S | F30: Edward | Andry | G30: {=_xludf.XLOOKUP(D30,'KPS #48'!D:D,'KPS #48'!G:G,0)} -> #NAME? | H30: {=_xludf.XLOOKUP(D30,'KPS #48'!D:D,'KPS #48'!H:H,0)} -> #NAME? | I30: =IF(AND(H30=0,G30=0),"No Delivery",IF(COUNTA(J30,L30,N30,P30,R30,T30,V30)=1,"Delivery",IF(COUNTA(J30,L30,N30,P30,R30,T30,V30)>1,"Partial Delivery",IF(COUNTA(J30,L30,N30,P30,R30,T30,V30)=0,"Will be Updated")))) -> #NAME? | J30: {=_xludf.XLOOKUP(D30,'KPS #48'!D:D,'KPS #48'!J:J,0)} -> #NAME? | K30: =_xludf.XLOOKUP($D30,#REF!,#REF!,0) -> #NAME? | L30: {=_xludf.XLOOKUP(D30,'KPS #48'!D:D,'KPS #48'!L:L,0)} -> #NAME? | M30: =_xludf.XLOOKUP($D30,#REF!,#REF!,0) -> #NAME? | N30: {=_xludf.XLOOKUP(D30,'KPS #48'!D:D,'KPS #48'!N:N,0)} -> #NAME? | O30: =_xludf.XLOOKUP($D30,#REF!,#REF!,0) -> #NAME? | P30: {=_xludf.XLOOKUP(D30,'KPS #48'!D:D,'KPS #48'!P:P,0)} -> #NAME? | Q30: =_xludf.XLOOKUP($D30,#REF!,#REF!,0) -> #NAME? | R30: {=_xludf.XLOOKUP(D30,'KPS #48'!D:D,'KPS #48'!R:R,0)} -> #NAME? | S30: =_xludf.XLOOKUP($D30,#REF!,#REF!,0) -> #NAME? | T30: {=_xludf.XLOOKUP(D30,'KPS #48'!D:D,'KPS #48'!T:T,0)} -> #NAME? | U30: =_xludf.XLOOKUP($D30,#REF!,#REF!,0) -> #NAME? | V30: {=_xludf.XLOOKUP(D30,'KPS #48'!D:D,'KPS #48'!V:V,0)} -> #NAME? | W30: =_xludf.XLOOKUP($D30,#REF!,#REF!,0) -> #NAME? | X30: =SUM(V30,T30,R30,P30,N30,L30,J30) -> #NAME? | Y30: =SUM(W30,U30,S30,Q30,O30,M30,K30) -> #NAME? | AA30: =X30*IFERROR(VLOOKUP(D30,'Brand List'!$B:$D,3,0),0) -> #NAME? | AB30: =H30*IFERROR(VLOOKUP(D30,'Brand List'!$B:$D,3,0),0) -> #NAME? | AC30: =AA30-AB30 -> #NAME? | AD30: =_xlfn.XLOOKUP(D30,[1]Summary!$E:$E,[1]Summary!$L:$L,0) -> 0 | AE30: =AD30*X30 -> #NAME?
A31: =D31 -> VKT16 | B31: PT Besuk Sukses Harmoni | C31: SKT 16 | D31: VKT16 | E31: Version Skt 16S | F31: Edward | Andry | G31: {=_xludf.XLOOKUP(D31,'KPS #48'!D:D,'KPS #48'!G:G,0)} -> #NAME? | H31: {=_xludf.XLOOKUP(D31,'KPS #48'!D:D,'KPS #48'!H:H,0)} -> #NAME? | I31: =IF(AND(H31=0,G31=0),"No Delivery",IF(COUNTA(J31,L31,N31,P31,R31,T31,V31)=1,"Delivery",IF(COUNTA(J31,L31,N31,P31,R31,T31,V31)>1,"Partial Delivery",IF(COUNTA(J31,L31,N31,P31,R31,T31,V31)=0,"Will be Updated")))) -> #NAME? | J31: {=_xludf.XLOOKUP(D31,'KPS #48'!D:D,'KPS #48'!J:J,0)} -> #NAME? | K31: =_xludf.XLOOKUP($D31,#REF!,#REF!,0) -> #NAME? | L31: {=_xludf.XLOOKUP(D31,'KPS #48'!D:D,'KPS #48'!L:L,0)} -> #NAME? | M31: =_xludf.XLOOKUP($D31,#REF!,#REF!,0) -> #NAME? | N31: {=_xludf.XLOOKUP(D31,'KPS #48'!D:D,'KPS #48'!N:N,0)} -> #NAME? | O31: =_xludf.XLOOKUP($D31,#REF!,#REF!,0) -> #NAME? | P31: {=_xludf.XLOOKUP(D31,'KPS #48'!D:D,'KPS #48'!P:P,0)} -> #NAME? | Q31: =_xludf.XLOOKUP($D31,#REF!,#REF!,0) -> #NAME? | R31: {=_xludf.XLOOKUP(D31,'KPS #48'!D:D,'KPS #48'!R:R,0)} -> #NAME? | S31: =_xludf.XLOOKUP($D31,#REF!,#REF!,0) -> #NAME? | T31: {=_xludf.XLOOKUP(D31,'KPS #48'!D:D,'KPS #48'!T:T,0)} -> #NAME? | U31: =_xludf.XLOOKUP($D31,#REF!,#REF!,0) -> #NAME? | V31: {=_xludf.XLOOKUP(D31,'KPS #48'!D:D,'KPS #48'!V:V,0)} -> #NAME? | W31: =_xludf.XLOOKUP($D31,#REF!,#REF!,0) -> #NAME? | X31: =SUM(V31,T31,R31,P31,N31,L31,J31) -> #NAME? | Y31: =SUM(W31,U31,S31,Q31,O31,M31,K31) -> #NAME? | AA31: =X31*IFERROR(VLOOKUP(D31,'Brand List'!$B:$D,3,0),0) -> #NAME? | AB31: =H31*IFERROR(VLOOKUP(D31,'Brand List'!$B:$D,3,0),0) -> #NAME? | AC31: =AA31-AB31 -> #NAME? | AD31: =_xlfn.XLOOKUP(D31,[1]Summary!$E:$E,[1]Summary!$L:$L,0) -> 0 | AE31: =AD31*X31 -> #NAME?
A32: =D32 -> SLT12 | B32: PT Batu Karang | C32: SKT 12 | D32: SLT12 | E32: Salitis (153) Skt 12S | F32: Edward | Andry | G32: {=_xludf.XLOOKUP(D32,'KPS #48'!D:D,'KPS #48'!G:G,0)} -> #NAME? | H32: {=_xludf.XLOOKUP(D32,'KPS #48'!D:D,'KPS #48'!H:H,0)} -> #NAME? | I32: =IF(AND(H32=0,G32=0),"No Delivery",IF(COUNTA(J32,L32,N32,P32,R32,T32,V32)=1,"Delivery",IF(COUNTA(J32,L32,N32,P32,R32,T32,V32)>1,"Partial Delivery",IF(COUNTA(J32,L32,N32,P32,R32,T32,V32)=0,"Will be Updated")))) -> #NAME? | J32: {=_xludf.XLOOKUP(D32,'KPS #48'!D:D,'KPS #48'!J:J,0)} -> #NAME? | K32: =_xludf.XLOOKUP($D32,#REF!,#REF!,0) -> #NAME? | L32: {=_xludf.XLOOKUP(D32,'KPS #48'!D:D,'KPS #48'!L:L,0)} -> #NAME? | M32: =_xludf.XLOOKUP($D32,#REF!,#REF!,0) -> #NAME? | N32: {=_xludf.XLOOKUP(D32,'KPS #48'!D:D,'KPS #48'!N:N,0)} -> #NAME? | O32: =_xludf.XLOOKUP($D32,#REF!,#REF!,0) -> #NAME? | P32: {=_xludf.XLOOKUP(D32,'KPS #48'!D:D,'KPS #48'!P:P,0)} -> #NAME? | Q32: =_xludf.XLOOKUP($D32,#REF!,#REF!,0) -> #NAME? | R32: {=_xludf.XLOOKUP(D32,'KPS #48'!D:D,'KPS #48'!R:R,0)} -> #NAME? | S32: =_xludf.XLOOKUP($D32,#REF!,#REF!,0) -> #NAME? | T32: {=_xludf.XLOOKUP(D32,'KPS #48'!D:D,'KPS #48'!T:T,0)} -> #NAME? | U32: =_xludf.XLOOKUP($D32,#REF!,#REF!,0) -> #NAME? | V32: {=_xludf.XLOOKUP(D32,'KPS #48'!D:D,'KPS #48'!V:V,0)} -> #NAME? | W32: =_xludf.XLOOKUP($D32,#REF!,#REF!,0) -> #NAME? | X32: =SUM(V32,T32,R32,P32,N32,L32,J32) -> #NAME? | Y32: =SUM(W32,U32,S32,Q32,O32,M32,K32) -> #NAME? | AA32: =X32*IFERROR(VLOOKUP(D32,'Brand List'!$B:$D,3,0),0) -> #NAME? | AB32: =H32*IFERROR(VLOOKUP(D32,'Brand List'!$B:$D,3,0),0) -> #NAME? | AC32: =AA32-AB32 -> #NAME? | AD32: =_xlfn.XLOOKUP(D32,[1]Summary!$E:$E,[1]Summary!$L:$L,0) -> 0 | AE32: =AD32*X32 -> #NAME?
A33: =D33 -> SLT16 | B33: PT Batu Karang | C33: SKT 16 | D33: SLT16 | E33: Salitis (153) Skt 16S | F33: Edward | Andry | G33: {=_xludf.XLOOKUP(D33,'KPS #48'!D:D,'KPS #48'!G:G,0)} -> #NAME? | H33: {=_xludf.XLOOKUP(D33,'KPS #48'!D:D,'KPS #48'!H:H,0)} -> #NAME? | I33: =IF(AND(H33=0,G33=0),"No Delivery",IF(COUNTA(J33,L33,N33,P33,R33,T33,V33)=1,"Delivery",IF(COUNTA(J33,L33,N33,P33,R33,T33,V33)>1,"Partial Delivery",IF(COUNTA(J33,L33,N33,P33,R33,T33,V33)=0,"Will be Updated")))) -> #NAME? | J33: {=_xludf.XLOOKUP(D33,'KPS #48'!D:D,'KPS #48'!J:J,0)} -> #NAME? | K33: =_xludf.XLOOKUP($D33,#REF!,#REF!,0) -> #NAME? | L33: {=_xludf.XLOOKUP(D33,'KPS #48'!D:D,'KPS #48'!L:L,0)} -> #NAME? | M33: =_xludf.XLOOKUP($D33,#REF!,#REF!,0) -> #NAME? | N33: {=_xludf.XLOOKUP(D33,'KPS #48'!D:D,'KPS #48'!N:N,0)} -> #NAME? | O33: =_xludf.XLOOKUP($D33,#REF!,#REF!,0) -> #NAME? | P33: {=_xludf.XLOOKUP(D33,'KPS #48'!D:D,'KPS #48'!P:P,0)} -> #NAME? | Q33: =_xludf.XLOOKUP($D33,#REF!,#REF!,0) -> #NAME? | R33: {=_xludf.XLOOKUP(D33,'KPS #48'!D:D,'KPS #48'!R:R,0)} -> #NAME? | S33: =_xludf.XLOOKUP($D33,#REF!,#REF!,0) -> #NAME? | T33: {=_xludf.XLOOKUP(D33,'KPS #48'!D:D,'KPS #48'!T:T,0)} -> #NAME? | U33: =_xludf.XLOOKUP($D33,#REF!,#REF!,0) -> #NAME? | V33: {=_xludf.XLOOKUP(D33,'KPS #48'!D:D,'KPS #48'!V:V,0)} -> #NAME? | W33: =_xludf.XLOOKUP($D33,#REF!,#REF!,0) -> #NAME? | X33: =SUM(V33,T33,R33,P33,N33,L33,J33) -> #NAME? | Y33: =SUM(W33,U33,S33,Q33,O33,M33,K33) -> #NAME? | AA33: =X33*IFERROR(VLOOKUP(D33,'Brand List'!$B:$D,3,0),0) -> #NAME? | AB33: =H33*IFERROR(VLOOKUP(D33,'Brand List'!$B:$D,3,0),0) -> #NAME? | AC33: =AA33-AB33 -> #NAME? | AD33: =_xlfn.XLOOKUP(D33,[1]Summary!$E:$E,[1]Summary!$L:$L,0) -> 0 | AE33: =AD33*X33 -> #NAME?
A34: =D34 -> SLT20 | B34: PT Batu Karang | C34: SKT 20 | D34: SLT20 | E34: Salitis (153) Skt 16S | F34: Edward | Andry | G34: {=_xludf.XLOOKUP(D34,'KPS #48'!D:D,'KPS #48'!G:G,0)} -> #NAME? | H34: {=_xludf.XLOOKUP(D34,'KPS #48'!D:D,'KPS #48'!H:H,0)} -> #NAME? | I34: =IF(AND(H34=0,G34=0),"No Delivery",IF(COUNTA(J34,L34,N34,P34,R34,T34,V34)=1,"Delivery",IF(COUNTA(J34,L34,N34,P34,R34,T34,V34)>1,"Partial Delivery",IF(COUNTA(J34,L34,N34,P34,R34,T34,V34)=0,"Will be Updated")))) -> #NAME? | J34: {=_xludf.XLOOKUP(D34,'KPS #48'!D:D,'KPS #48'!J:J,0)} -> #NAME? | K34: =_xludf.XLOOKUP($D34,#REF!,#REF!,0) -> #NAME? | L34: {=_xludf.XLOOKUP(D34,'KPS #48'!D:D,'KPS #48'!L:L,0)} -> #NAME? | M34: =_xludf.XLOOKUP($D34,#REF!,#REF!,0) -> #NAME? | N34: {=_xludf.XLOOKUP(D34,'KPS #48'!D:D,'KPS #48'!N:N,0)} -> #NAME? | O34: =_xludf.XLOOKUP($D34,#REF!,#REF!,0) -> #NAME? | P34: {=_xludf.XLOOKUP(D34,'KPS #48'!D:D,'KPS #48'!P:P,0)} -> #NAME? | Q34: =_xludf.XLOOKUP($D34,#REF!,#REF!,0) -> #NAME? | R34: {=_xludf.XLOOKUP(D34,'KPS #48'!D:D,'KPS #48'!R:R,0)} -> #NAME? | S34: =_xludf.XLOOKUP($D34,#REF!,#REF!,0) -> #NAME? | T34: {=_xludf.XLOOKUP(D34,'KPS #48'!D:D,'KPS #48'!T:T,0)} -> #NAME? | U34: =_xludf.XLOOKUP($D34,#REF!,#REF!,0) -> #NAME? | V34: {=_xludf.XLOOKUP(D34,'KPS #48'!D:D,'KPS #48'!V:V,0)} -> #NAME? | W34: =_xludf.XLOOKUP($D34,#REF!,#REF!,0) -> #NAME? | X34: =SUM(V34,T34,R34,P34,N34,L34,J34) -> #NAME? | Y34: =SUM(W34,U34,S34,Q34,O34,M34,K34) -> #NAME? | AA34: =X34*IFERROR(VLOOKUP(D34,'Brand List'!$B:$D,3,0),0) -> #NAME? | AB34: =H34*IFERROR(VLOOKUP(D34,'Brand List'!$B:$D,3,0),0) -> #NAME? | AC34: =AA34-AB34 -> #NAME? | AD34: =_xlfn.XLOOKUP(D34,[1]Summary!$E:$E,[1]Summary!$L:$L,0) -> 0 | AE34: =AD34*X34 -> #NAME?
A35: =D35 -> KBL12 | B35: CV Pancaran Sinar Mentari | C35: SKT 12 | D35: KBL12 | E35: Kabel Skt 12S | F35: Edward | Andry | G35: {=_xludf.XLOOKUP(D35,'KPS #48'!D:D,'KPS #48'!G:G,0)} -> #NAME? | H35: {=_xludf.XLOOKUP(D35,'KPS #48'!D:D,'KPS #48'!H:H,0)} -> #NAME? | I35: =IF(AND(H35=0,G35=0),"No Delivery",IF(COUNTA(J35,L35,N35,P35,R35,T35,V35)=1,"Delivery",IF(COUNTA(J35,L35,N35,P35,R35,T35,V35)>1,"Partial Delivery",IF(COUNTA(J35,L35,N35,P35,R35,T35,V35)=0,"Will be Updated")))) -> #NAME? | J35: {=_xludf.XLOOKUP(D35,'KPS #48'!D:D,'KPS #48'!J:J,0)} -> #NAME? | K35: =_xludf.XLOOKUP($D35,#REF!,#REF!,0) -> #NAME? | L35: {=_xludf.XLOOKUP(D35,'KPS #48'!D:D,'KPS #48'!L:L,0)} -> #NAME? | M35: =_xludf.XLOOKUP($D35,#REF!,#REF!,0) -> #NAME? | N35: {=_xludf.XLOOKUP(D35,'KPS #48'!D:D,'KPS #48'!N:N,0)} -> #NAME? | O35: =_xludf.XLOOKUP($D35,#REF!,#REF!,0) -> #NAME? | P35: {=_xludf.XLOOKUP(D35,'KPS #48'!D:D,'KPS #48'!P:P,0)} -> #NAME? | Q35: =_xludf.XLOOKUP($D35,#REF!,#REF!,0) -> #NAME? | R35: {=_xludf.XLOOKUP(D35,'KPS #48'!D:D,'KPS #48'!R:R,0)} -> #NAME? | S35: =_xludf.XLOOKUP($D35,#REF!,#REF!,0) -> #NAME? | T35: {=_xludf.XLOOKUP(D35,'KPS #48'!D:D,'KPS #48'!T:T,0)} -> #NAME? | U35: =_xludf.XLOOKUP($D35,#REF!,#REF!,0) -> #NAME? | V35: {=_xludf.XLOOKUP(D35,'KPS #48'!D:D,'KPS #48'!V:V,0)} -> #NAME? | W35: =_xludf.XLOOKUP($D35,#REF!,#REF!,0) -> #NAME? | X35: =SUM(V35,T35,R35,P35,N35,L35,J35) -> #NAME? | Y35: =SUM(W35,U35,S35,Q35,O35,M35,K35) -> #NAME? | Z35: Remaining 40 box po kps 45 to be confirm | AA35: =X35*IFERROR(VLOOKUP(D35,'Brand List'!$B:$D,3,0),0) -> #NAME? | AB35: =H35*IFERROR(VLOOKUP(D35,'Brand List'!$B:$D,3,0),0) -> #NAME? | AC35: =AA35-AB35 -> #NAME? | AD35: =_xlfn.XLOOKUP(D35,[1]Summary!$E:$E,[1]Summary!$L:$L,0) -> 0 | AE35: =AD35*X35 -> #NAME?
A36: =D36 -> LND20 | B36: CV Pancaran Sinar Mentari | C36: SKT 20 | D36: LND20 | E36: Lima Dan Dua Skt 20S | F36: Edward | Andry | G36: {=_xludf.XLOOKUP(D36,'KPS #48'!D:D,'KPS #48'!G:G,0)} -> #NAME? | H36: {=_xludf.XLOOKUP(D36,'KPS #48'!D:D,'KPS #48'!H:H,0)} -> #NAME? | I36: =IF(AND(H36=0,G36=0),"No Delivery",IF(COUNTA(J36,L36,N36,P36,R36,T36,V36)=1,"Delivery",IF(COUNTA(J36,L36,N36,P36,R36,T36,V36)>1,"Partial Delivery",IF(COUNTA(J36,L36,N36,P36,R36,T36,V36)=0,"Will be Updated")))) -> #NAME? | J36: {=_xludf.XLOOKUP(D36,'KPS #48'!D:D,'KPS #48'!J:J,0)} -> #NAME? | K36: =_xludf.XLOOKUP($D36,#REF!,#REF!,0) -> #NAME? | L36: {=_xludf.XLOOKUP(D36,'KPS #48'!D:D,'KPS #48'!L:L,0)} -> #NAME? | M36: =_xludf.XLOOKUP($D36,#REF!,#REF!,0) -> #NAME? | N36: {=_xludf.XLOOKUP(D36,'KPS #48'!D:D,'KPS #48'!N:N,0)} -> #NAME? | O36: =_xludf.XLOOKUP($D36,#REF!,#REF!,0) -> #NAME? | P36: {=_xludf.XLOOKUP(D36,'KPS #48'!D:D,'KPS #48'!P:P,0)} -> #NAME? | Q36: =_xludf.XLOOKUP($D36,#REF!,#REF!,0) -> #NAME? | R36: {=_xludf.XLOOKUP(D36,'KPS #48'!D:D,'KPS #48'!R:R,0)} -> #NAME? | S36: =_xludf.XLOOKUP($D36,#REF!,#REF!,0) -> #NAME? | T36: {=_xludf.XLOOKUP(D36,'KPS #48'!D:D,'KPS #48'!T:T,0)} -> #NAME? | U36: =_xludf.XLOOKUP($D36,#REF!,#REF!,0) -> #NAME? | V36: {=_xludf.XLOOKUP(D36,'KPS #48'!D:D,'KPS #48'!V:V,0)} -> #NAME? | W36: =_xludf.XLOOKUP($D36,#REF!,#REF!,0) -> #NAME? | X36: =SUM(V36,T36,R36,P36,N36,L36,J36) -> #NAME? | Y36: =SUM(W36,U36,S36,Q36,O36,M36,K36) -> #NAME? | AA36: =X36*IFERROR(VLOOKUP(D36,'Brand List'!$B:$D,3,0),0) -> #NAME? | AB36: =H36*IFERROR(VLOOKUP(D36,'Brand List'!$B:$D,3,0),0) -> #NAME? | AC36: =AA36-AB36 -> #NAME? | AD36: =_xlfn.XLOOKUP(D36,[1]Summary!$E:$E,[1]Summary!$L:$L,0) -> 0 | AE36: =AD36*X36 -> #NAME?
A37: =D37 -> BAJ12 | B37: PT Daun Emas Nustantara (DEN) | C37: SKT 12 | D37: BAJ12 | E37: Baja Skt 12S | F37: Vincent | Lariza | G37: {=_xludf.XLOOKUP(D37,'KPS #48'!D:D,'KPS #48'!G:G,0)} -> #NAME? | H37: {=_xludf.XLOOKUP(D37,'KPS #48'!D:D,'KPS #48'!H:H,0)} -> #NAME? | I37: =IF(AND(H37=0,G37=0),"No Delivery",IF(COUNTA(J37,L37,N37,P37,R37,T37,V37)=1,"Delivery",IF(COUNTA(J37,L37,N37,P37,R37,T37,V37)>1,"Partial Delivery",IF(COUNTA(J37,L37,N37,P37,R37,T37,V37)=0,"Will be Updated")))) -> #NAME? | J37: {=_xludf.XLOOKUP(D37,'KPS #48'!D:D,'KPS #48'!J:J,0)} -> #NAME? | K37: =_xludf.XLOOKUP($D37,#REF!,#REF!,0) -> #NAME? | L37: {=_xludf.XLOOKUP(D37,'KPS #48'!D:D,'KPS #48'!L:L,0)} -> #NAME? | M37: =_xludf.XLOOKUP($D37,#REF!,#REF!,0) -> #NAME? | N37: {=_xludf.XLOOKUP(D37,'KPS #48'!D:D,'KPS #48'!N:N,0)} -> #NAME? | O37: =_xludf.XLOOKUP($D37,#REF!,#REF!,0) -> #NAME? | P37: {=_xludf.XLOOKUP(D37,'KPS #48'!D:D,'KPS #48'!P:P,0)} -> #NAME? | Q37: =_xludf.XLOOKUP($D37,#REF!,#REF!,0) -> #NAME? | R37: {=_xludf.XLOOKUP(D37,'KPS #48'!D:D,'KPS #48'!R:R,0)} -> #NAME? | S37: =_xludf.XLOOKUP($D37,#REF!,#REF!,0) -> #NAME? | T37: {=_xludf.XLOOKUP(D37,'KPS #48'!D:D,'KPS #48'!T:T,0)} -> #NAME? | U37: =_xludf.XLOOKUP($D37,#REF!,#REF!,0) -> #NAME? | V37: {=_xludf.XLOOKUP(D37,'KPS #48'!D:D,'KPS #48'!V:V,0)} -> #NAME? | W37: =_xludf.XLOOKUP($D37,#REF!,#REF!,0) -> #NAME? | X37: =SUM(V37,T37,R37,P37,N37,L37,J37) -> #NAME? | Y37: =SUM(W37,U37,S37,Q37,O37,M37,K37) -> #NAME? | AA37: =X37*IFERROR(VLOOKUP(D37,'Brand List'!$B:$D,3,0),0) -> #NAME? | AB37: =H37*IFERROR(VLOOKUP(D37,'Brand List'!$B:$D,3,0),0) -> #NAME? | AC37: =AA37-AB37 -> #NAME? | AD37: =_xlfn.XLOOKUP(D37,[1]Summary!$E:$E,[1]Summary!$L:$L,0) -> 0 | AE37: =AD37*X37 -> #NAME?
A38: =D38 -> NIA16 | B38: PT Daun Emas Nustantara (DEN) | C38: SKT 12 | D38: NIA16 | E38: Nian Skt 16S | F38: Vincent | Lariza | G38: {=_xludf.XLOOKUP(D38,'KPS #48'!D:D,'KPS #48'!G:G,0)} -> #NAME? | H38: {=_xludf.XLOOKUP(D38,'KPS #48'!D:D,'KPS #48'!H:H,0)} -> #NAME? | I38: =IF(AND(H38=0,G38=0),"No Delivery",IF(COUNTA(J38,L38,N38,P38,R38,T38,V38)=1,"Delivery",IF(COUNTA(J38,L38,N38,P38,R38,T38,V38)>1,"Partial Delivery",IF(COUNTA(J38,L38,N38,P38,R38,T38,V38)=0,"Will be Updated")))) -> #NAME? | J38: {=_xludf.XLOOKUP(D38,'KPS #48'!D:D,'KPS #48'!J:J,0)} -> #NAME? | K38: =_xludf.XLOOKUP($D38,#REF!,#REF!,0) -> #NAME? | L38: {=_xludf.XLOOKUP(D38,'KPS #48'!D:D,'KPS #48'!L:L,0)} -> #NAME? | M38: =_xludf.XLOOKUP($D38,#REF!,#REF!,0) -> #NAME? | N38: {=_xludf.XLOOKUP(D38,'KPS #48'!D:D,'KPS #48'!N:N,0)} -> #NAME? | O38: =_xludf.XLOOKUP($D38,#REF!,#REF!,0) -> #NAME? | P38: {=_xludf.XLOOKUP(D38,'KPS #48'!D:D,'KPS #48'!P:P,0)} -> #NAME? | Q38: =_xludf.XLOOKUP($D38,#REF!,#REF!,0) -> #NAME? | R38: {=_xludf.XLOOKUP(D38,'KPS #48'!D:D,'KPS #48'!R:R,0)} -> #NAME? | S38: =_xludf.XLOOKUP($D38,#REF!,#REF!,0) -> #NAME? | T38: {=_xludf.XLOOKUP(D38,'KPS #48'!D:D,'KPS #48'!T:T,0)} -> #NAME? | U38: =_xludf.XLOOKUP($D38,#REF!,#REF!,0) -> #NAME? | V38: {=_xludf.XLOOKUP(D38,'KPS #48'!D:D,'KPS #48'!V:V,0)} -> #NAME? | W38: =_xludf.XLOOKUP($D38,#REF!,#REF!,0) -> #NAME? | X38: =SUM(V38,T38,R38,P38,N38,L38,J38) -> #NAME? | Y38: =SUM(W38,U38,S38,Q38,O38,M38,K38) -> #NAME? | Z38: GR Shift 3 | AA38: =X38*IFERROR(VLOOKUP(D38,'Brand List'!$B:$D,3,0),0) -> #NAME? | AB38: =H38*IFERROR(VLOOKUP(D38,'Brand List'!$B:$D,3,0),0) -> #NAME? | AC38: =AA38-AB38 -> #NAME? | AD38: =_xlfn.XLOOKUP(D38,[1]Summary!$E:$E,[1]Summary!$L:$L,0) -> 0 | AE38: =AD38*X38 -> #NAME?
